Workbook

Sheet Gesamtranking Print
A1: Jassstatistik Wädis 2026/2027
F5: Gesamtwertung
F7: Ranking | G7: Spieler | H7: Anzahl Pokale | I7: VH %
F8: 1 | G8: =IFERROR(VLOOKUP(F8,$A$110:$B$118,2,0),"DOPPEL") -> Chäli | H8: =SUMIFS($C$111:$C$118,$B$111:$B$118,G8) -> 25 | I8: =SUMIFS(Rohdaten!$AH$143:$AH$150,Rohdaten!$D$143:$D$150,'Gesamtranking Print'!$G8) -> 0.34782609
F9: 2 | G9: =IFERROR(VLOOKUP(F9,$A$110:$B$118,2,0),"DOPPEL") -> Goonse | H9: =SUMIFS($C$111:$C$118,$B$111:$B$118,G9) -> 16 | I9: =SUMIFS(Rohdaten!$AH$143:$AH$150,Rohdaten!$D$143:$D$150,'Gesamtranking Print'!$G9) -> 0.30434783
F10: 3 | G10: =IFERROR(VLOOKUP(F10,$A$110:$B$118,2,0),"DOPPEL") -> Fuchs | H10: =SUMIFS($C$111:$C$118,$B$111:$B$118,G10) -> 2 | I10: =SUMIFS(Rohdaten!$AH$143:$AH$150,Rohdaten!$D$143:$D$150,'Gesamtranking Print'!$G10) -> 0.29166667
F11: 4 | G11: =IFERROR(VLOOKUP(F11,$A$110:$B$118,2,0),"DOPPEL") -> Küng | H11: =SUMIFS($C$111:$C$118,$B$111:$B$118,G11) -> 1 | I11: =SUMIFS(Rohdaten!$AH$143:$AH$150,Rohdaten!$D$143:$D$150,'Gesamtranking Print'!$G11) -> 0.34782609
A14: Strich
A16: Ranking | B16: Spieler | C16: Total Striche | D16: Pokal | F16: Ranking | G16: Spieler | H16: Total Berg | I16: Pokal | K16: Ranking | L16: Spieler | M16: ø Anzahl Striche/Abend | N16: Pokal
A17: 1 | B17: Goonse | C17: 18 | D17: 1 | F17: 1 | G17: Goonse | H17: 6 | I17: 1 | K17: 1 | L17: Goonse | M17: 9 | N17: 1
A18: 2 | B18: Chäli | C18: 0 | D18: 1 | F18: 2 | G18: Chäli | H18: 0 | I18: 1 | K18: 2 | L18: Chäli | M18: 0 | N18: 1
A19: 3 | B19: Fuchs | C19: 11 | F19: 3 | G19: Fuchs | H19: 3 | K19: 3 | L19: Fuchs | M19: 5.5
A20: 4 | B20: DOPPEL | C20: 0 | F20: 4 | G20: Doppel | H20: 0 | K20: 4 | L20: DOPPEL | M20: 0
A22: Ranking | B22: Spieler | C22: ø Anzahl Striche/Spiel | D22: Pokal | F22: Ranking | G22: Spieler | H22: Total Schneider | I22: Pokal | K22: Ranking | L22: Spieler | M22: Total Kontermatch | N22: Pokal
A23: 1 | B23: Goonse | C23: 2 | D23: 1 | F23: 1 | G23: Fuchs | H23: 0 | K23: 1 | L23: Fuchs | M23: 0
A24: 2 | B24: Chäli | C24: 0 | D24: 1 | F24: 2 | G24: DOPPEL | H24: 0 | K24: 2 | L24: DOPPEL | M24: 0
A25: 3 | B25: Fuchs | C25: 1.2222222 | F25: 3 | G25: DOPPEL | H25: 0 | K25: 3 | L25: DOPPEL | M25: 0
A26: 4 | B26: DOPPEL | C26: 0 | F26: 4 | G26: DOPPEL | H26: 0 | K26: 4 | L26: DOPPEL | M26: 0
A28: Pünkt
A30: Ranking | B30: Spieler | C30: Total Punkte | D30: Pokal | F30: Ranking | G30: Spieler | H30: ø Anzahl Punkte/Abend | I30: Pokal | K30: Ranking | L30: Spieler | M30: ø Anzahl Punkte/Spiel | N30: Pokal
A31: 1 | B31: Goonse | C31: 26192 | D31: 1 | F31: 1 | G31: Goonse | H31: 13096 | I31: 1 | K31: 1 | L31: Goonse | M31: 2910.2222 | N31: 1
A32: 2 | B32: Chäli | C32: 0 | D32: 1 | F32: 2 | G32: Chäli | H32: 0 | I32: 1 | K32: 2 | L32: Chäli | M32: 0 | N32: 1
A33: 3 | B33: Fuchs | C33: 25299 | F33: 3 | G33: Fuchs | H33: 12649.5 | K33: 3 | L33: Fuchs | M33: 2811
A34: 4 | B34: DOPPEL | C34: 0 | F34: 4 | G34: DOPPEL | H34: 0 | K34: 4 | L34: DOPPEL | M34: 0
A36: Mätsch
A38: Ranking | B38: Spieler | C38: Total Anzahl Match | D38: Pokal | F38: Ranking | G38: Spieler | H38: Total Punkte Match* | I38: Pokal | K38: Ranking | L38: Spieler | M38: Anzahl Match 1fach | N38: Pokal
A39: 1 | B39: Goonse | C39: 2 | D39: 1 | F39: 1 | G39: Goonse | H39: 1285 | I39: 1 | K39: 1 | L39: Fuchs | M39: 0
A40: 2 | B40: Chäli | C40: 0 | D40: 1 | F40: 2 | G40: Chäli | H40: 0 | I40: 1 | K40: 2 | L40: DOPPEL | M40: 0
A41: 3 | B41: Fuchs | C41: 0 | F41: 3 | G41: Fuchs | H41: 0 | K41: 3 | L41: DOPPEL | M41: 0
A42: 4 | B42: DOPPEL | C42: 0 | F42: 4 | G42: DOPPEL | H42: 0 | K42: 4 | L42: DOPPEL | M42: 0
A44: Ranking | B44: Spieler | C44: Anzahl Match 2fach | D44: Pokal | F44: Ranking | G44: Spieler | H44: Anzahl Match 3fach | I44: Pokal | K44: Ranking | L44: Spieler | M44: Anzahl Match 4fach | N44: Pokal
A45: 1 | B45: Goonse | C45: 1 | D45: 1 | F45: 1 | G45: Goonse | H45: 1 | I45: 1 | K45: 1 | L45: Fuchs | M45: 0
A46: 2 | B46: Chäli | C46: 0 | D46: 1 | F46: 2 | G46: Chäli | H46: 0 | I46: 1 | K46: 2 | L46: DOPPEL | M46: 0
A47: 3 | B47: Fuchs | C47: 0 | F47: 3 | G47: Fuchs | H47: 0 | K47: 3 | L47: DOPPEL | M47: 0
A48: 4 | B48: DOPPEL | C48: 0 | F48: 4 | G48: DOPPEL | H48: 0 | K48: 4 | L48: DOPPEL | M48: 0
A50: Wiise
A52: Ranking | B52: Spieler | C52: Total Punkte Weisen* | D52: Pokal | F52: Ranking | G52: Spieler | H52: Anzahl Weisen 20er | I52: Pokal | K52: Ranking | L52: Spieler | M52: Punkte Weisen 20er* | N52: Pokal
A53: 1 | B53: Chäli | C53: 3820 | D53: 1 | F53: 1 | G53: Chäli | H53: 22 | I53: 1 | K53: 1 | L53: Chäli | M53: 1220 | N53: 1
A54: 2 | B54: Goonse | C54: 2020 | F54: 2 | G54: Fuchs | H54: 15 | K54: 2 | L54: Küng | M54: 940
A55: 3 | B55: Küng | C55: 1740 | F55: 3 | G55: Küng | H55: 14 | K55: 3 | L55: Fuchs | M55: 900
...

Sheet Gesamtranking
A1: Jassstatistik Wädis
F3: Gesamtwertung
F5: Ranking | G5: Spieler | H5: Anzahl Pokale
F6: 1 | G6: =IFERROR(VLOOKUP(F6,[1]Detail!X:AQ,20,0),"DOPPEL") -> Chäli | H6: =SUMIFS([1]Detail!$S$99:$S$107,[1]Detail!$C$99:$C$107,[1]Übersicht!$B6) -> #VALUE!
F7: 2 | G7: =IFERROR(VLOOKUP(F7,[1]Detail!X:AQ,20,0),"DOPPEL") -> Berg | H7: =SUMIFS([1]Detail!$S$99:$S$107,[1]Detail!$C$99:$C$107,[1]Übersicht!$B7) -> #VALUE!
F8: 3 | G8: =IFERROR(VLOOKUP(F8,[1]Detail!X:AQ,20,0),"DOPPEL") -> Rogerio | H8: =SUMIFS([1]Detail!$S$99:$S$107,[1]Detail!$C$99:$C$107,[1]Übersicht!$B8) -> #VALUE!
F9: 4 | G9: =IFERROR(VLOOKUP(F9,[1]Detail!X:AQ,20,0),"DOPPEL") -> Fisi | H9: =SUMIFS([1]Detail!$S$99:$S$107,[1]Detail!$C$99:$C$107,[1]Übersicht!$B9) -> #VALUE!
A12: Strich
A14: Ranking | B14: Spieler | C14: Total Striche | D14: Pokal | F14: Ranking | G14: Spieler | H14: Total Berg | I14: Pokal | K14: Ranking | L14: Spieler | M14: ø Anzahl Striche/Abend | N14: Pokal
A15: 1 | B15: =IFERROR(VLOOKUP(A15,Rohdaten!CQ:EL,48,0),"DOPPEL") -> Goonse | C15: =SUMIFS(Rohdaten!$AQ$143:$AQ$150,Rohdaten!$D$143:$D$150,Gesamtranking!B15) -> 18 | F15: 1 | G15: =IFERROR(VLOOKUP(F15,Rohdaten!CR:EL,47,0),"Doppel") -> Goonse | H15: =SUMIFS(Rohdaten!$AP$143:$AP$150,Rohdaten!$D$143:$D$150,Gesamtranking!G15) -> 6 | K15: 1 | L15: =IFERROR(VLOOKUP(K15,Rohdaten!CT:EL,45,0),"DOPPEL") -> Goonse | M15: =SUMIFS(Rohdaten!$CS$143:$CS$150,Rohdaten!$D$143:$D$150,Gesamtranking!L15) -> 9
A16: 2 | B16: =IFERROR(VLOOKUP(A16,Rohdaten!CQ:EL,48,0),"DOPPEL") -> DOPPEL | C16: =SUMIFS(Rohdaten!$AQ$143:$AQ$150,Rohdaten!$D$143:$D$150,Gesamtranking!B16) -> 0 | F16: 2 | G16: =IFERROR(VLOOKUP(F16,Rohdaten!CR:EL,47,0),"Doppel") -> Doppel | H16: =SUMIFS(Rohdaten!$AP$143:$AP$150,Rohdaten!$D$143:$D$150,Gesamtranking!G16) -> 0 | K16: 2 | L16: =IFERROR(VLOOKUP(K16,Rohdaten!CT:EL,45,0),"DOPPEL") -> DOPPEL | M16: =SUMIFS(Rohdaten!$CS$143:$CS$150,Rohdaten!$D$143:$D$150,Gesamtranking!L16) -> 0
A17: 3 | B17: =IFERROR(VLOOKUP(A17,Rohdaten!CQ:EL,48,0),"DOPPEL") -> Fuchs | C17: =SUMIFS(Rohdaten!$AQ$143:$AQ$150,Rohdaten!$D$143:$D$150,Gesamtranking!B17) -> 11 | F17: 3 | G17: =IFERROR(VLOOKUP(F17,Rohdaten!CR:EL,47,0),"Doppel") -> Fuchs | H17: =SUMIFS(Rohdaten!$AP$143:$AP$150,Rohdaten!$D$143:$D$150,Gesamtranking!G17) -> 3 | K17: 3 | L17: =IFERROR(VLOOKUP(K17,Rohdaten!CT:EL,45,0),"DOPPEL") -> Fuchs | M17: =SUMIFS(Rohdaten!$CS$143:$CS$150,Rohdaten!$D$143:$D$150,Gesamtranking!L17) -> 5.5
A18: 4 | B18: =IFERROR(VLOOKUP(A18,Rohdaten!CQ:EL,48,0),"DOPPEL") -> DOPPEL | C18: =SUMIFS(Rohdaten!$AQ$143:$AQ$150,Rohdaten!$D$143:$D$150,Gesamtranking!B18) -> 0 | F18: 4 | G18: =IFERROR(VLOOKUP(F18,Rohdaten!CR:EL,47,0),"Doppel") -> Doppel | H18: =SUMIFS(Rohdaten!$AP$143:$AP$150,Rohdaten!$D$143:$D$150,Gesamtranking!G18) -> 0 | K18: 4 | L18: =IFERROR(VLOOKUP(K18,Rohdaten!CT:EL,45,0),"DOPPEL") -> DOPPEL | M18: =SUMIFS(Rohdaten!$CS$143:$CS$150,Rohdaten!$D$143:$D$150,Gesamtranking!L18) -> 0
A20: Ranking | B20: Spieler | C20: ø Anzahl Striche/Spiel | D20: Pokal | F20: Ranking | G20: Spieler | H20: Total Schneider | I20: Pokal | K20: Ranking | L20: Spieler | M20: Total Kontermatch | N20: Pokal
A21: 1 | B21: =IFERROR(VLOOKUP(A21,Rohdaten!DY:EL,14,0),"DOPPEL") -> Goonse | C21: =SUMIFS(Rohdaten!$DX$143:$DX$150,Rohdaten!$D$143:$D$150,Gesamtranking!B21) -> 2 | F21: 1 | G21: =IFERROR(VLOOKUP(F21,Rohdaten!CU:EL,44,0),"DOPPEL") -> Fuchs | H21: =SUMIFS(Rohdaten!$AR$143:$AR$150,Rohdaten!$D$143:$D$150,Gesamtranking!G21) -> 0 | K21: 1 | L21: =IFERROR(VLOOKUP(K21,Rohdaten!DZ:EL,13,0),"DOPPEL") -> Fuchs | M21: =SUMIFS(Rohdaten!$AS$143:$AS$150,Rohdaten!$D$143:$D$150,Gesamtranking!L21) -> 0
A22: 2 | B22: =IFERROR(VLOOKUP(A22,Rohdaten!DY:EL,14,0),"DOPPEL") -> DOPPEL | C22: =SUMIFS(Rohdaten!$DX$143:$DX$150,Rohdaten!$D$143:$D$150,Gesamtranking!B22) -> 0 | F22: 2 | G22: =IFERROR(VLOOKUP(F22,Rohdaten!CU:EL,44,0),"DOPPEL") -> DOPPEL | H22: =SUMIFS(Rohdaten!$AR$143:$AR$150,Rohdaten!$D$143:$D$150,Gesamtranking!G22) -> 0 | K22: 2 | L22: =IFERROR(VLOOKUP(K22,Rohdaten!DZ:EL,13,0),"DOPPEL") -> DOPPEL | M22: =SUMIFS(Rohdaten!$AS$143:$AS$150,Rohdaten!$D$143:$D$150,Gesamtranking!L22) -> 0
A23: 3 | B23: =IFERROR(VLOOKUP(A23,Rohdaten!DY:EL,14,0),"DOPPEL") -> Fuchs | C23: =SUMIFS(Rohdaten!$DX$143:$DX$150,Rohdaten!$D$143:$D$150,Gesamtranking!B23) -> 1.2222222 | F23: 3 | G23: =IFERROR(VLOOKUP(F23,Rohdaten!CU:EL,44,0),"DOPPEL") -> DOPPEL | H23: =SUMIFS(Rohdaten!$AR$143:$AR$150,Rohdaten!$D$143:$D$150,Gesamtranking!G23) -> 0 | K23: 3 | L23: =IFERROR(VLOOKUP(K23,Rohdaten!DZ:EL,13,0),"DOPPEL") -> DOPPEL | M23: =SUMIFS(Rohdaten!$AS$143:$AS$150,Rohdaten!$D$143:$D$150,Gesamtranking!L23) -> 0
A24: 4 | B24: =IFERROR(VLOOKUP(A24,Rohdaten!DY:EL,14,0),"DOPPEL") -> DOPPEL | C24: =SUMIFS(Rohdaten!$DX$143:$DX$150,Rohdaten!$D$143:$D$150,Gesamtranking!B24) -> 0 | F24: 4 | G24: =IFERROR(VLOOKUP(F24,Rohdaten!CU:EL,44,0),"DOPPEL") -> DOPPEL | H24: =SUMIFS(Rohdaten!$AR$143:$AR$150,Rohdaten!$D$143:$D$150,Gesamtranking!G24) -> 0 | K24: 4 | L24: =IFERROR(VLOOKUP(K24,Rohdaten!DZ:EL,13,0),"DOPPEL") -> DOPPEL | M24: =SUMIFS(Rohdaten!$AS$143:$AS$150,Rohdaten!$D$143:$D$150,Gesamtranking!L24) -> 0
A26: Pünkt
A28: Ranking | B28: Spieler | C28: Total Punkte | D28: Pokal | F28: Ranking | G28: Spieler | H28: ø Anzahl Punkte/Abend | I28: Pokal | K28: Ranking | L28: Spieler | M28: ø Anzahl Punkte/Spiel | N28: Pokal
A29: 1 | B29: =IFERROR(VLOOKUP(A29,Rohdaten!CV:EL,43,0),"DOPPEL") -> Goonse | C29: =SUMIFS(Rohdaten!$O$143:$O$150,Rohdaten!$D$143:$D$150,Gesamtranking!B29) -> 26192 | F29: 1 | G29: =IFERROR(VLOOKUP(F29,Rohdaten!CX:EL,41,0),"DOPPEL") -> Goonse | H29: =SUMIFS(Rohdaten!$CW$143:$CW$150,Rohdaten!$D$143:$D$150,Gesamtranking!G29) -> 13096 | K29: 1 | L29: =IFERROR(VLOOKUP(K29,Rohdaten!DW:EL,16,0),"DOPPEL") -> Goonse | M29: =SUMIFS(Rohdaten!$DV$143:$DV$150,Rohdaten!$D$143:$D$150,Gesamtranking!L29) -> 2910.2222
A30: 2 | B30: =IFERROR(VLOOKUP(A30,Rohdaten!CV:EL,43,0),"DOPPEL") -> DOPPEL | C30: =SUMIFS(Rohdaten!$O$143:$O$150,Rohdaten!$D$143:$D$150,Gesamtranking!B30) -> 0 | F30: 2 | G30: =IFERROR(VLOOKUP(F30,Rohdaten!CX:EL,41,0),"DOPPEL") -> DOPPEL | H30: =SUMIFS(Rohdaten!$CW$143:$CW$150,Rohdaten!$D$143:$D$150,Gesamtranking!G30) -> 0 | K30: 2 | L30: =IFERROR(VLOOKUP(K30,Rohdaten!DW:EL,16,0),"DOPPEL") -> DOPPEL | M30: =SUMIFS(Rohdaten!$DV$143:$DV$150,Rohdaten!$D$143:$D$150,Gesamtranking!L30) -> 0
A31: 3 | B31: =IFERROR(VLOOKUP(A31,Rohdaten!CV:EL,43,0),"DOPPEL") -> Fuchs | C31: =SUMIFS(Rohdaten!$O$143:$O$150,Rohdaten!$D$143:$D$150,Gesamtranking!B31) -> 25299 | F31: 3 | G31: =IFERROR(VLOOKUP(F31,Rohdaten!CX:EL,41,0),"DOPPEL") -> Fuchs | H31: =SUMIFS(Rohdaten!$CW$143:$CW$150,Rohdaten!$D$143:$D$150,Gesamtranking!G31) -> 12649.5 | K31: 3 | L31: =IFERROR(VLOOKUP(K31,Rohdaten!DW:EL,16,0),"DOPPEL") -> Fuchs | M31: =SUMIFS(Rohdaten!$DV$143:$DV$150,Rohdaten!$D$143:$D$150,Gesamtranking!L31) -> 2811
A32: 4 | B32: =IFERROR(VLOOKUP(A32,Rohdaten!CV:EL,43,0),"DOPPEL") -> DOPPEL | C32: =SUMIFS(Rohdaten!$O$143:$O$150,Rohdaten!$D$143:$D$150,Gesamtranking!B32) -> 0 | F32: 4 | G32: =IFERROR(VLOOKUP(F32,Rohdaten!CX:EL,41,0),"DOPPEL") -> DOPPEL | H32: =SUMIFS(Rohdaten!$CW$143:$CW$150,Rohdaten!$D$143:$D$150,Gesamtranking!G32) -> 0 | K32: 4 | L32: =IFERROR(VLOOKUP(K32,Rohdaten!DW:EL,16,0),"DOPPEL") -> DOPPEL | M32: =SUMIFS(Rohdaten!$DV$143:$DV$150,Rohdaten!$D$143:$D$150,Gesamtranking!L32) -> 0
A34: Mätsch
A36: Ranking | B36: Spieler | C36: Total Anzahl Match | D36: Pokal | F36: Ranking | G36: Spieler | H36: Total Punkte Match* | I36: Pokal | K36: Ranking | L36: Spieler | M36: Anzahl Match 1fach | N36: Pokal
A37: 1 | B37: =IFERROR(VLOOKUP(A37,Rohdaten!CY:EL,40,0),"DOPPEL") -> Goonse | C37: =SUMIFS(Rohdaten!$AO$143:$AO$150,Rohdaten!$D$143:$D$150,Gesamtranking!B37) -> 2 | F37: 1 | G37: =IFERROR(VLOOKUP(F37,Rohdaten!CZ:EL,39,0),"DOPPEL") -> Goonse | H37: =SUMIFS(Rohdaten!$CO$143:$CO$150,Rohdaten!$D$143:$D$150,Gesamtranking!G37) -> 1285 | K37: 1 | L37: =IFERROR(VLOOKUP(K37,Rohdaten!DA:EL,38,0),"DOPPEL") -> Fuchs | M37: =SUMIFS(Rohdaten!$AI$143:$AI$150,Rohdaten!$D$143:$D$150,Gesamtranking!L37) -> 0
A38: 2 | B38: =IFERROR(VLOOKUP(A38,Rohdaten!CY:EL,40,0),"DOPPEL") -> DOPPEL | C38: =SUMIFS(Rohdaten!$AO$143:$AO$150,Rohdaten!$D$143:$D$150,Gesamtranking!B38) -> 0 | F38: 2 | G38: =IFERROR(VLOOKUP(F38,Rohdaten!CZ:EL,39,0),"DOPPEL") -> DOPPEL | H38: =SUMIFS(Rohdaten!$CO$143:$CO$150,Rohdaten!$D$143:$D$150,Gesamtranking!G38) -> 0 | K38: 2 | L38: =IFERROR(VLOOKUP(K38,Rohdaten!DA:EL,38,0),"DOPPEL") -> DOPPEL | M38: =SUMIFS(Rohdaten!$AI$143:$AI$150,Rohdaten!$D$143:$D$150,Gesamtranking!L38) -> 0
A39: 3 | B39: =IFERROR(VLOOKUP(A39,Rohdaten!CY:EL,40,0),"DOPPEL") -> Fuchs | C39: =SUMIFS(Rohdaten!$AO$143:$AO$150,Rohdaten!$D$143:$D$150,Gesamtranking!B39) -> 0 | F39: 3 | G39: =IFERROR(VLOOKUP(F39,Rohdaten!CZ:EL,39,0),"DOPPEL") -> Fuchs | H39: =SUMIFS(Rohdaten!$CO$143:$CO$150,Rohdaten!$D$143:$D$150,Gesamtranking!G39) -> 0 | K39: 3 | L39: =IFERROR(VLOOKUP(K39,Rohdaten!DA:EL,38,0),"DOPPEL") -> DOPPEL | M39: =SUMIFS(Rohdaten!$AI$143:$AI$150,Rohdaten!$D$143:$D$150,Gesamtranking!L39) -> 0
A40: 4 | B40: =IFERROR(VLOOKUP(A40,Rohdaten!CY:EL,40,0),"DOPPEL") -> DOPPEL | C40: =SUMIFS(Rohdaten!$AO$143:$AO$150,Rohdaten!$D$143:$D$150,Gesamtranking!B40) -> 0 | F40: 4 | G40: =IFERROR(VLOOKUP(F40,Rohdaten!CZ:EL,39,0),"DOPPEL") -> DOPPEL | H40: =SUMIFS(Rohdaten!$CO$143:$CO$150,Rohdaten!$D$143:$D$150,Gesamtranking!G40) -> 0 | K40: 4 | L40: =IFERROR(VLOOKUP(K40,Rohdaten!DA:EL,38,0),"DOPPEL") -> DOPPEL | M40: =SUMIFS(Rohdaten!$AI$143:$AI$150,Rohdaten!$D$143:$D$150,Gesamtranking!L40) -> 0
A42: Ranking | B42: Spieler | C42: Anzahl Match 2fach | D42: Pokal | F42: Ranking | G42: Spieler | H42: Anzahl Match 3fach | I42: Pokal | K42: Ranking | L42: Spieler | M42: Anzahl Match 4fach | N42: Pokal
A43: 1 | B43: =IFERROR(VLOOKUP(A43,Rohdaten!DB:EL,37,0),"DOPPEL") -> Goonse | C43: =SUMIFS(Rohdaten!$AK$152:$AK$159,Rohdaten!$D$143:$D$150,Gesamtranking!B43) -> 1 | F43: 1 | G43: =IFERROR(VLOOKUP(F43,Rohdaten!DC:EL,36,0),"DOPPEL") -> Goonse | H43: =SUMIFS(Rohdaten!$AN$152:$AN$159,Rohdaten!$D$143:$D$150,Gesamtranking!G43) -> 1 | K43: 1 | L43: =IFERROR(VLOOKUP(K43,Rohdaten!DD:EL,35,0),"DOPPEL") -> Fuchs | M43: =SUMIFS(Rohdaten!$AL$143:$AL$150,Rohdaten!$D$143:$D$150,Gesamtranking!L43) -> 0
A44: 2 | B44: =IFERROR(VLOOKUP(A44,Rohdaten!DB:EL,37,0),"DOPPEL") -> DOPPEL | C44: =SUMIFS(Rohdaten!$AK$152:$AK$159,Rohdaten!$D$143:$D$150,Gesamtranking!B44) -> 0 | F44: 2 | G44: =IFERROR(VLOOKUP(F44,Rohdaten!DC:EL,36,0),"DOPPEL") -> DOPPEL | H44: =SUMIFS(Rohdaten!$AN$152:$AN$159,Rohdaten!$D$143:$D$150,Gesamtranking!G44) -> 0 | K44: 2 | L44: =IFERROR(VLOOKUP(K44,Rohdaten!DD:EL,35,0),"DOPPEL") -> DOPPEL | M44: =SUMIFS(Rohdaten!$AL$143:$AL$150,Rohdaten!$D$143:$D$150,Gesamtranking!L44) -> 0
A45: 3 | B45: =IFERROR(VLOOKUP(A45,Rohdaten!DB:EL,37,0),"DOPPEL") -> Fuchs | C45: =SUMIFS(Rohdaten!$AK$152:$AK$159,Rohdaten!$D$143:$D$150,Gesamtranking!B45) -> 0 | F45: 3 | G45: =IFERROR(VLOOKUP(F45,Rohdaten!DC:EL,36,0),"DOPPEL") -> Fuchs | H45: =SUMIFS(Rohdaten!$AN$152:$AN$159,Rohdaten!$D$143:$D$150,Gesamtranking!G45) -> 0 | K45: 3 | L45: =IFERROR(VLOOKUP(K45,Rohdaten!DD:EL,35,0),"DOPPEL") -> DOPPEL | M45: =SUMIFS(Rohdaten!$AL$143:$AL$150,Rohdaten!$D$143:$D$150,Gesamtranking!L45) -> 0
A46: 4 | B46: =IFERROR(VLOOKUP(A46,Rohdaten!DB:EL,37,0),"DOPPEL") -> DOPPEL | C46: =SUMIFS(Rohdaten!$AK$152:$AK$159,Rohdaten!$D$143:$D$150,Gesamtranking!B46) -> 0 | F46: 4 | G46: =IFERROR(VLOOKUP(F46,Rohdaten!DC:EL,36,0),"DOPPEL") -> DOPPEL | H46: =SUMIFS(Rohdaten!$AN$152:$AN$159,Rohdaten!$D$143:$D$150,Gesamtranking!G46) -> 0 | K46: 4 | L46: =IFERROR(VLOOKUP(K46,Rohdaten!DD:EL,35,0),"DOPPEL") -> DOPPEL | M46: =SUMIFS(Rohdaten!$AL$143:$AL$150,Rohdaten!$D$143:$D$150,Gesamtranking!L46) -> 0
A48: Wiise
A50: Ranking | B50: Spieler | C50: Total Punkte Weisen* | D50: Pokal | F50: Ranking | G50: Spieler | H50: Anzahl Weisen 20er | I50: Pokal | K50: Ranking | L50: Spieler | M50: Punkte Weisen 20er* | N50: Pokal
A51: 1 | B51: =IFERROR(VLOOKUP(A51,Rohdaten!DE:EL,34,0),"DOPPEL") -> Chäli | C51: =SUMIFS(Rohdaten!$CJ$143:$CJ$150,Rohdaten!$D$143:$D$150,Gesamtranking!B51) -> 3820 | F51: 1 | G51: =IFERROR(VLOOKUP(F51,Rohdaten!DF:EL,33,0),"DOPPEL") -> Chäli | H51: =SUMIFS(Rohdaten!$BA$143:$BA$150,Rohdaten!$D$143:$D$150,Gesamtranking!G51) -> 22 | K51: 1 | L51: =IFERROR(VLOOKUP(K51,Rohdaten!DG:EL,32,0),"DOPPEL") -> Chäli | M51: =SUMIFS(Rohdaten!$CE$143:$CE$150,Rohdaten!$D$143:$D$150,Gesamtranking!L51) -> 1220
A52: 2 | B52: =IFERROR(VLOOKUP(A52,Rohdaten!DE:EL,34,0),"DOPPEL") -> Goonse | C52: =SUMIFS(Rohdaten!$CJ$143:$CJ$150,Rohdaten!$D$143:$D$150,Gesamtranking!B52) -> 2020 | F52: 2 | G52: =IFERROR(VLOOKUP(F52,Rohdaten!DF:EL,33,0),"DOPPEL") -> Fuchs | H52: =SUMIFS(Rohdaten!$BA$143:$BA$150,Rohdaten!$D$143:$D$150,Gesamtranking!G52) -> 15 | K52: 2 | L52: =IFERROR(VLOOKUP(K52,Rohdaten!DG:EL,32,0),"DOPPEL") -> Küng | M52: =SUMIFS(Rohdaten!$CE$143:$CE$150,Rohdaten!$D$143:$D$150,Gesamtranking!L52) -> 940
A53: 3 | B53: =IFERROR(VLOOKUP(A53,Rohdaten!DE:EL,34,0),"DOPPEL") -> Küng | C53: =SUMIFS(Rohdaten!$CJ$143:$CJ$150,Rohdaten!$D$143:$D$150,Gesamtranking!B53) -> 1740 | F53: 3 | G53: =IFERROR(VLOOKUP(F53,Rohdaten!DF:EL,33,0),"DOPPEL") -> Küng | H53: =SUMIFS(Rohdaten!$BA$143:$BA$150,Rohdaten!$D$143:$D$150,Gesamtranking!G53) -> 14 | K53: 3 | L53: =IFERROR(VLOOKUP(K53,Rohdaten!DG:EL,32,0),"DOPPEL") -> Fuchs | M53: =SUMIFS(Rohdaten!$CE$143:$CE$150,Rohdaten!$D$143:$D$150,Gesamtranking!L53) -> 900
...

Sheet Einzelabend
A1: ="Übersicht Jassabend" -> Übersicht Jassabend
A3: Datum: | C3: 46111
F4: Vorhand/Rückhand | M4: Weisen
C5: Player | D5: Vorhand % | E5: Wiis p.P. | F5: Eichle | G5: Schelle | H5: Schilten | I5: Rose | J5: Une | K5: Obe | M5: Eichlen | N5: Schelle | O5: Schilten | P5: Rose | Q5: Une | R5: Obe
A6: Team 1 | B6: =$C$3&A6 -> 46111Team 1 | C6: =VLOOKUP(B6,Rohdaten!C:D,2,0) -> Fuchs | D6: =SUMIFS(Rohdaten!AH:AH,Rohdaten!C:C,Einzelabend!B6,Rohdaten!D:D,Einzelabend!C6) -> 0.125 | E6: =SUMIFS(Rohdaten!$CJ:$CJ,Rohdaten!$A:$A,Einzelabend!$C$3,Rohdaten!$D:$D,Einzelabend!$C6) -> 500 | F6: =SUMIFS(Rohdaten!V:V,Rohdaten!$A:$A,Einzelabend!$C$3,Rohdaten!$D:$D,Einzelabend!$C6)+SUMIFS(Rohdaten!$AB:$AB,Rohdaten!$A:$A,Einzelabend!$C$3,Rohdaten!$D:$D,Einzelabend!$C6) -> 1 | G6: =SUMIFS(Rohdaten!W:W,Rohdaten!$A:$A,Einzelabend!$C$3,Rohdaten!$D:$D,Einzelabend!$C6)+SUMIFS(Rohdaten!$AC:$AC,Rohdaten!$A:$A,Einzelabend!$C$3,Rohdaten!$D:$D,Einzelabend!$C6) -> 1 | H6: =SUMIFS(Rohdaten!X:X,Rohdaten!$A:$A,Einzelabend!$C$3,Rohdaten!$D:$D,Einzelabend!$C6)+SUMIFS(Rohdaten!$AD:$AD,Rohdaten!$A:$A,Einzelabend!$C$3,Rohdaten!$D:$D,Einzelabend!$C6) -> 0 | I6: =SUMIFS(Rohdaten!Y:Y,Rohdaten!$A:$A,Einzelabend!$C$3,Rohdaten!$D:$D,Einzelabend!$C6)+SUMIFS(Rohdaten!$AE:$AE,Rohdaten!$A:$A,Einzelabend!$C$3,Rohdaten!$D:$D,Einzelabend!$C6) -> 2 | J6: =SUMIFS(Rohdaten!Z:Z,Rohdaten!$A:$A,Einzelabend!$C$3,Rohdaten!$D:$D,Einzelabend!$C6)+SUMIFS(Rohdaten!$AF:$AF,Rohdaten!$A:$A,Einzelabend!$C$3,Rohdaten!$D:$D,Einzelabend!$C6) -> 1 | K6: =SUMIFS(Rohdaten!AA:AA,Rohdaten!$A:$A,Einzelabend!$C$3,Rohdaten!$D:$D,Einzelabend!$C6)+SUMIFS(Rohdaten!$AG:$AG,Rohdaten!$A:$A,Einzelabend!$C$3,Rohdaten!$D:$D,Einzelabend!$C6) -> 1 | M6: =(SUMIFS(Rohdaten!AU:AU,Rohdaten!$A:$A,Einzelabend!$C$3,Rohdaten!$D:$D,Einzelabend!$C6))+(SUMIFS(Rohdaten!BB:BB,Rohdaten!$A:$A,Einzelabend!$C$3,Rohdaten!$D:$D,Einzelabend!$C6))+(SUMIFS(Rohdaten!BI:BI,Rohdaten!$A:$A,Einzelabend!$C$3,Rohdaten!$D:$D,Einzelabend!$C6))+(SUMIFS(Rohdaten!BP:BP,Rohdaten!$A:$A,Einzelabend!$C$3,Rohdaten!$D:$D,Einzelabend!$C6))+(SUMIFS(Rohdaten!BW:BW,Rohdaten!$A:$A,Einzelabend!$C$3,Rohdaten!$D:$D,Einzelabend!$C6)) -> 0 | N6: =(SUMIFS(Rohdaten!AV:AV,Rohdaten!$A:$A,Einzelabend!$C$3,Rohdaten!$D:$D,Einzelabend!$C6))+(SUMIFS(Rohdaten!BC:BC,Rohdaten!$A:$A,Einzelabend!$C$3,Rohdaten!$D:$D,Einzelabend!$C6))+(SUMIFS(Rohdaten!BJ:BJ,Rohdaten!$A:$A,Einzelabend!$C$3,Rohdaten!$D:$D,Einzelabend!$C6))+(SUMIFS(Rohdaten!BQ:BQ,Rohdaten!$A:$A,Einzelabend!$C$3,Rohdaten!$D:$D,Einzelabend!$C6))+(SUMIFS(Rohdaten!BX:BX,Rohdaten!$A:$A,Einzelabend!$C$3,Rohdaten!$D:$D,Einzelabend!$C6)) -> 1 | O6: =(SUMIFS(Rohdaten!AW:AW,Rohdaten!$A:$A,Einzelabend!$C$3,Rohdaten!$D:$D,Einzelabend!$C6))+(SUMIFS(Rohdaten!BD:BD,Rohdaten!$A:$A,Einzelabend!$C$3,Rohdaten!$D:$D,Einzelabend!$C6))+(SUMIFS(Rohdaten!BK:BK,Rohdaten!$A:$A,Einzelabend!$C$3,Rohdaten!$D:$D,Einzelabend!$C6))+(SUMIFS(Rohdaten!BR:BR,Rohdaten!$A:$A,Einzelabend!$C$3,Rohdaten!$D:$D,Einzelabend!$C6))+(SUMIFS(Rohdaten!BY:BY,Rohdaten!$A:$A,Einzelabend!$C$3,Rohdaten!$D:$D,Einzelabend!$C6)) -> 0 | P6: =(SUMIFS(Rohdaten!AX:AX,Rohdaten!$A:$A,Einzelabend!$C$3,Rohdaten!$D:$D,Einzelabend!$C6))+(SUMIFS(Rohdaten!BE:BE,Rohdaten!$A:$A,Einzelabend!$C$3,Rohdaten!$D:$D,Einzelabend!$C6))+(SUMIFS(Rohdaten!BL:BL,Rohdaten!$A:$A,Einzelabend!$C$3,Rohdaten!$D:$D,Einzelabend!$C6))+(SUMIFS(Rohdaten!BS:BS,Rohdaten!$A:$A,Einzelabend!$C$3,Rohdaten!$D:$D,Einzelabend!$C6))+(SUMIFS(Rohdaten!BZ:BZ,Rohdaten!$A:$A,Einzelabend!$C$3,Rohdaten!$D:$D,Einzelabend!$C6)) -> 3 | Q6: =(SUMIFS(Rohdaten!AY:AY,Rohdaten!$A:$A,Einzelabend!$C$3,Rohdaten!$D:$D,Einzelabend!$C6))+(SUMIFS(Rohdaten!BF:BF,Rohdaten!$A:$A,Einzelabend!$C$3,Rohdaten!$D:$D,Einzelabend!$C6))+(SUMIFS(Rohdaten!BM:BM,Rohdaten!$A:$A,Einzelabend!$C$3,Rohdaten!$D:$D,Einzelabend!$C6))+(SUMIFS(Rohdaten!BT:BT,Rohdaten!$A:$A,Einzelabend!$C$3,Rohdaten!$D:$D,Einzelabend!$C6))+(SUMIFS(Rohdaten!CA:CA,Rohdaten!$A:$A,Einzelabend!$C$3,Rohdaten!$D:$D,Einzelabend!$C6)) -> 0 | R6: =(SUMIFS(Rohdaten!AZ:AZ,Rohdaten!$A:$A,Einzelabend!$C$3,Rohdaten!$D:$D,Einzelabend!$C6))+(SUMIFS(Rohdaten!BG:BG,Rohdaten!$A:$A,Einzelabend!$C$3,Rohdaten!$D:$D,Einzelabend!$C6))+(SUMIFS(Rohdaten!BN:BN,Rohdaten!$A:$A,Einzelabend!$C$3,Rohdaten!$D:$D,Einzelabend!$C6))+(SUMIFS(Rohdaten!BU:BU,Rohdaten!$A:$A,Einzelabend!$C$3,Rohdaten!$D:$D,Einzelabend!$C6))+(SUMIFS(Rohdaten!CB:CB,Rohdaten!$A:$A,Einzelabend!$C$3,Rohdaten!$D:$D,Einzelabend!$C6)) -> 1
A7: Team 1.1 | B7: =$C$3&A7 -> 46111Team 1.1 | C7: =VLOOKUP(B7,Rohdaten!C:D,2,0) -> Küng | D7: =SUMIFS(Rohdaten!AH:AH,Rohdaten!C:C,Einzelabend!B7,Rohdaten!D:D,Einzelabend!C7) -> 0.375 | E7: =SUMIFS(Rohdaten!$CJ:$CJ,Rohdaten!$A:$A,Einzelabend!$C$3,Rohdaten!$D:$D,Einzelabend!$C7) -> 400 | F7: =SUMIFS(Rohdaten!V:V,Rohdaten!$A:$A,Einzelabend!$C$3,Rohdaten!$D:$D,Einzelabend!$C7)+SUMIFS(Rohdaten!$AB:$AB,Rohdaten!$A:$A,Einzelabend!$C$3,Rohdaten!$D:$D,Einzelabend!$C7) -> 0 | G7: =SUMIFS(Rohdaten!W:W,Rohdaten!$A:$A,Einzelabend!$C$3,Rohdaten!$D:$D,Einzelabend!$C7)+SUMIFS(Rohdaten!$AC:$AC,Rohdaten!$A:$A,Einzelabend!$C$3,Rohdaten!$D:$D,Einzelabend!$C7) -> 0 | H7: =SUMIFS(Rohdaten!X:X,Rohdaten!$A:$A,Einzelabend!$C$3,Rohdaten!$D:$D,Einzelabend!$C7)+SUMIFS(Rohdaten!$AD:$AD,Rohdaten!$A:$A,Einzelabend!$C$3,Rohdaten!$D:$D,Einzelabend!$C7) -> 2 | I7: =SUMIFS(Rohdaten!Y:Y,Rohdaten!$A:$A,Einzelabend!$C$3,Rohdaten!$D:$D,Einzelabend!$C7)+SUMIFS(Rohdaten!$AE:$AE,Rohdaten!$A:$A,Einzelabend!$C$3,Rohdaten!$D:$D,Einzelabend!$C7) -> 4 | J7: =SUMIFS(Rohdaten!Z:Z,Rohdaten!$A:$A,Einzelabend!$C$3,Rohdaten!$D:$D,Einzelabend!$C7)+SUMIFS(Rohdaten!$AF:$AF,Rohdaten!$A:$A,Einzelabend!$C$3,Rohdaten!$D:$D,Einzelabend!$C7) -> 1 | K7: =SUMIFS(Rohdaten!AA:AA,Rohdaten!$A:$A,Einzelabend!$C$3,Rohdaten!$D:$D,Einzelabend!$C7)+SUMIFS(Rohdaten!$AG:$AG,Rohdaten!$A:$A,Einzelabend!$C$3,Rohdaten!$D:$D,Einzelabend!$C7) -> 3 | M7: =(SUMIFS(Rohdaten!AU:AU,Rohdaten!$A:$A,Einzelabend!$C$3,Rohdaten!$D:$D,Einzelabend!$C7))+(SUMIFS(Rohdaten!BB:BB,Rohdaten!$A:$A,Einzelabend!$C$3,Rohdaten!$D:$D,Einzelabend!$C7))+(SUMIFS(Rohdaten!BI:BI,Rohdaten!$A:$A,Einzelabend!$C$3,Rohdaten!$D:$D,Einzelabend!$C7))+(SUMIFS(Rohdaten!BP:BP,Rohdaten!$A:$A,Einzelabend!$C$3,Rohdaten!$D:$D,Einzelabend!$C7))+(SUMIFS(Rohdaten!BW:BW,Rohdaten!$A:$A,Einzelabend!$C$3,Rohdaten!$D:$D,Einzelabend!$C7)) -> 0 | N7: =(SUMIFS(Rohdaten!AV:AV,Rohdaten!$A:$A,Einzelabend!$C$3,Rohdaten!$D:$D,Einzelabend!$C7))+(SUMIFS(Rohdaten!BC:BC,Rohdaten!$A:$A,Einzelabend!$C$3,Rohdaten!$D:$D,Einzelabend!$C7))+(SUMIFS(Rohdaten!BJ:BJ,Rohdaten!$A:$A,Einzelabend!$C$3,Rohdaten!$D:$D,Einzelabend!$C7))+(SUMIFS(Rohdaten!BQ:BQ,Rohdaten!$A:$A,Einzelabend!$C$3,Rohdaten!$D:$D,Einzelabend!$C7))+(SUMIFS(Rohdaten!BX:BX,Rohdaten!$A:$A,Einzelabend!$C$3,Rohdaten!$D:$D,Einzelabend!$C7)) -> 0 | O7: =(SUMIFS(Rohdaten!AW:AW,Rohdaten!$A:$A,Einzelabend!$C$3,Rohdaten!$D:$D,Einzelabend!$C7))+(SUMIFS(Rohdaten!BD:BD,Rohdaten!$A:$A,Einzelabend!$C$3,Rohdaten!$D:$D,Einzelabend!$C7))+(SUMIFS(Rohdaten!BK:BK,Rohdaten!$A:$A,Einzelabend!$C$3,Rohdaten!$D:$D,Einzelabend!$C7))+(SUMIFS(Rohdaten!BR:BR,Rohdaten!$A:$A,Einzelabend!$C$3,Rohdaten!$D:$D,Einzelabend!$C7))+(SUMIFS(Rohdaten!BY:BY,Rohdaten!$A:$A,Einzelabend!$C$3,Rohdaten!$D:$D,Einzelabend!$C7)) -> 1 | P7: =(SUMIFS(Rohdaten!AX:AX,Rohdaten!$A:$A,Einzelabend!$C$3,Rohdaten!$D:$D,Einzelabend!$C7))+(SUMIFS(Rohdaten!BE:BE,Rohdaten!$A:$A,Einzelabend!$C$3,Rohdaten!$D:$D,Einzelabend!$C7))+(SUMIFS(Rohdaten!BL:BL,Rohdaten!$A:$A,Einzelabend!$C$3,Rohdaten!$D:$D,Einzelabend!$C7))+(SUMIFS(Rohdaten!BS:BS,Rohdaten!$A:$A,Einzelabend!$C$3,Rohdaten!$D:$D,Einzelabend!$C7))+(SUMIFS(Rohdaten!BZ:BZ,Rohdaten!$A:$A,Einzelabend!$C$3,Rohdaten!$D:$D,Einzelabend!$C7)) -> 3 | Q7: =(SUMIFS(Rohdaten!AY:AY,Rohdaten!$A:$A,Einzelabend!$C$3,Rohdaten!$D:$D,Einzelabend!$C7))+(SUMIFS(Rohdaten!BF:BF,Rohdaten!$A:$A,Einzelabend!$C$3,Rohdaten!$D:$D,Einzelabend!$C7))+(SUMIFS(Rohdaten!BM:BM,Rohdaten!$A:$A,Einzelabend!$C$3,Rohdaten!$D:$D,Einzelabend!$C7))+(SUMIFS(Rohdaten!BT:BT,Rohdaten!$A:$A,Einzelabend!$C$3,Rohdaten!$D:$D,Einzelabend!$C7))+(SUMIFS(Rohdaten!CA:CA,Rohdaten!$A:$A,Einzelabend!$C$3,Rohdaten!$D:$D,Einzelabend!$C7)) -> 1 | R7: =(SUMIFS(Rohdaten!AZ:AZ,Rohdaten!$A:$A,Einzelabend!$C$3,Rohdaten!$D:$D,Einzelabend!$C7))+(SUMIFS(Rohdaten!BG:BG,Rohdaten!$A:$A,Einzelabend!$C$3,Rohdaten!$D:$D,Einzelabend!$C7))+(SUMIFS(Rohdaten!BN:BN,Rohdaten!$A:$A,Einzelabend!$C$3,Rohdaten!$D:$D,Einzelabend!$C7))+(SUMIFS(Rohdaten!BU:BU,Rohdaten!$A:$A,Einzelabend!$C$3,Rohdaten!$D:$D,Einzelabend!$C7))+(SUMIFS(Rohdaten!CB:CB,Rohdaten!$A:$A,Einzelabend!$C$3,Rohdaten!$D:$D,Einzelabend!$C7)) -> 1
A8: Team 2 | B8: =$C$3&A8 -> 46111Team 2 | C8: =VLOOKUP(B8,Rohdaten!C:D,2,0) -> Goonse | D8: =SUMIFS(Rohdaten!AH:AH,Rohdaten!C:C,Einzelabend!B8,Rohdaten!D:D,Einzelabend!C8) -> 0.25 | E8: =SUMIFS(Rohdaten!$CJ:$CJ,Rohdaten!$A:$A,Einzelabend!$C$3,Rohdaten!$D:$D,Einzelabend!$C8) -> 700 | F8: =SUMIFS(Rohdaten!V:V,Rohdaten!$A:$A,Einzelabend!$C$3,Rohdaten!$D:$D,Einzelabend!$C8)+SUMIFS(Rohdaten!$AB:$AB,Rohdaten!$A:$A,Einzelabend!$C$3,Rohdaten!$D:$D,Einzelabend!$C8) -> 0 | G8: =SUMIFS(Rohdaten!W:W,Rohdaten!$A:$A,Einzelabend!$C$3,Rohdaten!$D:$D,Einzelabend!$C8)+SUMIFS(Rohdaten!$AC:$AC,Rohdaten!$A:$A,Einzelabend!$C$3,Rohdaten!$D:$D,Einzelabend!$C8) -> 3 | H8: =SUMIFS(Rohdaten!X:X,Rohdaten!$A:$A,Einzelabend!$C$3,Rohdaten!$D:$D,Einzelabend!$C8)+SUMIFS(Rohdaten!$AD:$AD,Rohdaten!$A:$A,Einzelabend!$C$3,Rohdaten!$D:$D,Einzelabend!$C8) -> 1 | I8: =SUMIFS(Rohdaten!Y:Y,Rohdaten!$A:$A,Einzelabend!$C$3,Rohdaten!$D:$D,Einzelabend!$C8)+SUMIFS(Rohdaten!$AE:$AE,Rohdaten!$A:$A,Einzelabend!$C$3,Rohdaten!$D:$D,Einzelabend!$C8) -> 1 | J8: =SUMIFS(Rohdaten!Z:Z,Rohdaten!$A:$A,Einzelabend!$C$3,Rohdaten!$D:$D,Einzelabend!$C8)+SUMIFS(Rohdaten!$AF:$AF,Rohdaten!$A:$A,Einzelabend!$C$3,Rohdaten!$D:$D,Einzelabend!$C8) -> 2 | K8: =SUMIFS(Rohdaten!AA:AA,Rohdaten!$A:$A,Einzelabend!$C$3,Rohdaten!$D:$D,Einzelabend!$C8)+SUMIFS(Rohdaten!$AG:$AG,Rohdaten!$A:$A,Einzelabend!$C$3,Rohdaten!$D:$D,Einzelabend!$C8) -> 1 | M8: =(SUMIFS(Rohdaten!AU:AU,Rohdaten!$A:$A,Einzelabend!$C$3,Rohdaten!$D:$D,Einzelabend!$C8))+(SUMIFS(Rohdaten!BB:BB,Rohdaten!$A:$A,Einzelabend!$C$3,Rohdaten!$D:$D,Einzelabend!$C8))+(SUMIFS(Rohdaten!BI:BI,Rohdaten!$A:$A,Einzelabend!$C$3,Rohdaten!$D:$D,Einzelabend!$C8))+(SUMIFS(Rohdaten!BP:BP,Rohdaten!$A:$A,Einzelabend!$C$3,Rohdaten!$D:$D,Einzelabend!$C8))+(SUMIFS(Rohdaten!BW:BW,Rohdaten!$A:$A,Einzelabend!$C$3,Rohdaten!$D:$D,Einzelabend!$C8)) -> 0 | N8: =(SUMIFS(Rohdaten!AV:AV,Rohdaten!$A:$A,Einzelabend!$C$3,Rohdaten!$D:$D,Einzelabend!$C8))+(SUMIFS(Rohdaten!BC:BC,Rohdaten!$A:$A,Einzelabend!$C$3,Rohdaten!$D:$D,Einzelabend!$C8))+(SUMIFS(Rohdaten!BJ:BJ,Rohdaten!$A:$A,Einzelabend!$C$3,Rohdaten!$D:$D,Einzelabend!$C8))+(SUMIFS(Rohdaten!BQ:BQ,Rohdaten!$A:$A,Einzelabend!$C$3,Rohdaten!$D:$D,Einzelabend!$C8))+(SUMIFS(Rohdaten!BX:BX,Rohdaten!$A:$A,Einzelabend!$C$3,Rohdaten!$D:$D,Einzelabend!$C8)) -> 1 | O8: =(SUMIFS(Rohdaten!AW:AW,Rohdaten!$A:$A,Einzelabend!$C$3,Rohdaten!$D:$D,Einzelabend!$C8))+(SUMIFS(Rohdaten!BD:BD,Rohdaten!$A:$A,Einzelabend!$C$3,Rohdaten!$D:$D,Einzelabend!$C8))+(SUMIFS(Rohdaten!BK:BK,Rohdaten!$A:$A,Einzelabend!$C$3,Rohdaten!$D:$D,Einzelabend!$C8))+(SUMIFS(Rohdaten!BR:BR,Rohdaten!$A:$A,Einzelabend!$C$3,Rohdaten!$D:$D,Einzelabend!$C8))+(SUMIFS(Rohdaten!BY:BY,Rohdaten!$A:$A,Einzelabend!$C$3,Rohdaten!$D:$D,Einzelabend!$C8)) -> 1 | P8: =(SUMIFS(Rohdaten!AX:AX,Rohdaten!$A:$A,Einzelabend!$C$3,Rohdaten!$D:$D,Einzelabend!$C8))+(SUMIFS(Rohdaten!BE:BE,Rohdaten!$A:$A,Einzelabend!$C$3,Rohdaten!$D:$D,Einzelabend!$C8))+(SUMIFS(Rohdaten!BL:BL,Rohdaten!$A:$A,Einzelabend!$C$3,Rohdaten!$D:$D,Einzelabend!$C8))+(SUMIFS(Rohdaten!BS:BS,Rohdaten!$A:$A,Einzelabend!$C$3,Rohdaten!$D:$D,Einzelabend!$C8))+(SUMIFS(Rohdaten!BZ:BZ,Rohdaten!$A:$A,Einzelabend!$C$3,Rohdaten!$D:$D,Einzelabend!$C8)) -> 1 | Q8: =(SUMIFS(Rohdaten!AY:AY,Rohdaten!$A:$A,Einzelabend!$C$3,Rohdaten!$D:$D,Einzelabend!$C8))+(SUMIFS(Rohdaten!BF:BF,Rohdaten!$A:$A,Einzelabend!$C$3,Rohdaten!$D:$D,Einzelabend!$C8))+(SUMIFS(Rohdaten!BM:BM,Rohdaten!$A:$A,Einzelabend!$C$3,Rohdaten!$D:$D,Einzelabend!$C8))+(SUMIFS(Rohdaten!BT:BT,Rohdaten!$A:$A,Einzelabend!$C$3,Rohdaten!$D:$D,Einzelabend!$C8))+(SUMIFS(Rohdaten!CA:CA,Rohdaten!$A:$A,Einzelabend!$C$3,Rohdaten!$D:$D,Einzelabend!$C8)) -> 1 | R8: =(SUMIFS(Rohdaten!AZ:AZ,Rohdaten!$A:$A,Einzelabend!$C$3,Rohdaten!$D:$D,Einzelabend!$C8))+(SUMIFS(Rohdaten!BG:BG,Rohdaten!$A:$A,Einzelabend!$C$3,Rohdaten!$D:$D,Einzelabend!$C8))+(SUMIFS(Rohdaten!BN:BN,Rohdaten!$A:$A,Einzelabend!$C$3,Rohdaten!$D:$D,Einzelabend!$C8))+(SUMIFS(Rohdaten!BU:BU,Rohdaten!$A:$A,Einzelabend!$C$3,Rohdaten!$D:$D,Einzelabend!$C8))+(SUMIFS(Rohdaten!CB:CB,Rohdaten!$A:$A,Einzelabend!$C$3,Rohdaten!$D:$D,Einzelabend!$C8)) -> 0
A9: Team 2.1 | B9: =$C$3&A9 -> 46111Team 2.1 | C9: =VLOOKUP(B9,Rohdaten!C:D,2,0) -> Chäli | D9: =SUMIFS(Rohdaten!AH:AH,Rohdaten!C:C,Einzelabend!B9,Rohdaten!D:D,Einzelabend!C9) -> 0.25 | E9: =SUMIFS(Rohdaten!$CJ:$CJ,Rohdaten!$A:$A,Einzelabend!$C$3,Rohdaten!$D:$D,Einzelabend!$C9) -> 1040 | F9: =SUMIFS(Rohdaten!V:V,Rohdaten!$A:$A,Einzelabend!$C$3,Rohdaten!$D:$D,Einzelabend!$C9)+SUMIFS(Rohdaten!$AB:$AB,Rohdaten!$A:$A,Einzelabend!$C$3,Rohdaten!$D:$D,Einzelabend!$C9) -> 2 | G9: =SUMIFS(Rohdaten!W:W,Rohdaten!$A:$A,Einzelabend!$C$3,Rohdaten!$D:$D,Einzelabend!$C9)+SUMIFS(Rohdaten!$AC:$AC,Rohdaten!$A:$A,Einzelabend!$C$3,Rohdaten!$D:$D,Einzelabend!$C9) -> 1 | H9: =SUMIFS(Rohdaten!X:X,Rohdaten!$A:$A,Einzelabend!$C$3,Rohdaten!$D:$D,Einzelabend!$C9)+SUMIFS(Rohdaten!$AD:$AD,Rohdaten!$A:$A,Einzelabend!$C$3,Rohdaten!$D:$D,Einzelabend!$C9) -> 3 | I9: =SUMIFS(Rohdaten!Y:Y,Rohdaten!$A:$A,Einzelabend!$C$3,Rohdaten!$D:$D,Einzelabend!$C9)+SUMIFS(Rohdaten!$AE:$AE,Rohdaten!$A:$A,Einzelabend!$C$3,Rohdaten!$D:$D,Einzelabend!$C9) -> 0 | J9: =SUMIFS(Rohdaten!Z:Z,Rohdaten!$A:$A,Einzelabend!$C$3,Rohdaten!$D:$D,Einzelabend!$C9)+SUMIFS(Rohdaten!$AF:$AF,Rohdaten!$A:$A,Einzelabend!$C$3,Rohdaten!$D:$D,Einzelabend!$C9) -> 2 | K9: =SUMIFS(Rohdaten!AA:AA,Rohdaten!$A:$A,Einzelabend!$C$3,Rohdaten!$D:$D,Einzelabend!$C9)+SUMIFS(Rohdaten!$AG:$AG,Rohdaten!$A:$A,Einzelabend!$C$3,Rohdaten!$D:$D,Einzelabend!$C9) -> 0 | M9: =(SUMIFS(Rohdaten!AU:AU,Rohdaten!$A:$A,Einzelabend!$C$3,Rohdaten!$D:$D,Einzelabend!$C9))+(SUMIFS(Rohdaten!BB:BB,Rohdaten!$A:$A,Einzelabend!$C$3,Rohdaten!$D:$D,Einzelabend!$C9))+(SUMIFS(Rohdaten!BI:BI,Rohdaten!$A:$A,Einzelabend!$C$3,Rohdaten!$D:$D,Einzelabend!$C9))+(SUMIFS(Rohdaten!BP:BP,Rohdaten!$A:$A,Einzelabend!$C$3,Rohdaten!$D:$D,Einzelabend!$C9))+(SUMIFS(Rohdaten!BW:BW,Rohdaten!$A:$A,Einzelabend!$C$3,Rohdaten!$D:$D,Einzelabend!$C9)) -> 0 | N9: =(SUMIFS(Rohdaten!AV:AV,Rohdaten!$A:$A,Einzelabend!$C$3,Rohdaten!$D:$D,Einzelabend!$C9))+(SUMIFS(Rohdaten!BC:BC,Rohdaten!$A:$A,Einzelabend!$C$3,Rohdaten!$D:$D,Einzelabend!$C9))+(SUMIFS(Rohdaten!BJ:BJ,Rohdaten!$A:$A,Einzelabend!$C$3,Rohdaten!$D:$D,Einzelabend!$C9))+(SUMIFS(Rohdaten!BQ:BQ,Rohdaten!$A:$A,Einzelabend!$C$3,Rohdaten!$D:$D,Einzelabend!$C9))+(SUMIFS(Rohdaten!BX:BX,Rohdaten!$A:$A,Einzelabend!$C$3,Rohdaten!$D:$D,Einzelabend!$C9)) -> 1 | O9: =(SUMIFS(Rohdaten!AW:AW,Rohdaten!$A:$A,Einzelabend!$C$3,Rohdaten!$D:$D,Einzelabend!$C9))+(SUMIFS(Rohdaten!BD:BD,Rohdaten!$A:$A,Einzelabend!$C$3,Rohdaten!$D:$D,Einzelabend!$C9))+(SUMIFS(Rohdaten!BK:BK,Rohdaten!$A:$A,Einzelabend!$C$3,Rohdaten!$D:$D,Einzelabend!$C9))+(SUMIFS(Rohdaten!BR:BR,Rohdaten!$A:$A,Einzelabend!$C$3,Rohdaten!$D:$D,Einzelabend!$C9))+(SUMIFS(Rohdaten!BY:BY,Rohdaten!$A:$A,Einzelabend!$C$3,Rohdaten!$D:$D,Einzelabend!$C9)) -> 2 | P9: =(SUMIFS(Rohdaten!AX:AX,Rohdaten!$A:$A,Einzelabend!$C$3,Rohdaten!$D:$D,Einzelabend!$C9))+(SUMIFS(Rohdaten!BE:BE,Rohdaten!$A:$A,Einzelabend!$C$3,Rohdaten!$D:$D,Einzelabend!$C9))+(SUMIFS(Rohdaten!BL:BL,Rohdaten!$A:$A,Einzelabend!$C$3,Rohdaten!$D:$D,Einzelabend!$C9))+(SUMIFS(Rohdaten!BS:BS,Rohdaten!$A:$A,Einzelabend!$C$3,Rohdaten!$D:$D,Einzelabend!$C9))+(SUMIFS(Rohdaten!BZ:BZ,Rohdaten!$A:$A,Einzelabend!$C$3,Rohdaten!$D:$D,Einzelabend!$C9)) -> 1 | Q9: =(SUMIFS(Rohdaten!AY:AY,Rohdaten!$A:$A,Einzelabend!$C$3,Rohdaten!$D:$D,Einzelabend!$C9))+(SUMIFS(Rohdaten!BF:BF,Rohdaten!$A:$A,Einzelabend!$C$3,Rohdaten!$D:$D,Einzelabend!$C9))+(SUMIFS(Rohdaten!BM:BM,Rohdaten!$A:$A,Einzelabend!$C$3,Rohdaten!$D:$D,Einzelabend!$C9))+(SUMIFS(Rohdaten!BT:BT,Rohdaten!$A:$A,Einzelabend!$C$3,Rohdaten!$D:$D,Einzelabend!$C9))+(SUMIFS(Rohdaten!CA:CA,Rohdaten!$A:$A,Einzelabend!$C$3,Rohdaten!$D:$D,Einzelabend!$C9)) -> 1 | R9: =(SUMIFS(Rohdaten!AZ:AZ,Rohdaten!$A:$A,Einzelabend!$C$3,Rohdaten!$D:$D,Einzelabend!$C9))+(SUMIFS(Rohdaten!BG:BG,Rohdaten!$A:$A,Einzelabend!$C$3,Rohdaten!$D:$D,Einzelabend!$C9))+(SUMIFS(Rohdaten!BN:BN,Rohdaten!$A:$A,Einzelabend!$C$3,Rohdaten!$D:$D,Einzelabend!$C9))+(SUMIFS(Rohdaten!BU:BU,Rohdaten!$A:$A,Einzelabend!$C$3,Rohdaten!$D:$D,Einzelabend!$C9))+(SUMIFS(Rohdaten!CB:CB,Rohdaten!$A:$A,Einzelabend!$C$3,Rohdaten!$D:$D,Einzelabend!$C9)) -> 4
M13: Weisen
M14: Eichlen | N14: Schelle | O14: Schilten | P14: Rose | Q14: Une | R14: Obe | S14: Summe
L15: =C6 -> Fuchs | M15: =(SUMIFS(Rohdaten!AU:AU,Rohdaten!$A:$A,Einzelabend!$C$3,Rohdaten!$D:$D,Einzelabend!$C6)*20)+(SUMIFS(Rohdaten!BB:BB,Rohdaten!$A:$A,Einzelabend!$C$3,Rohdaten!$D:$D,Einzelabend!$C6)*50)+(SUMIFS(Rohdaten!BI:BI,Rohdaten!$A:$A,Einzelabend!$C$3,Rohdaten!$D:$D,Einzelabend!$C6)*100)+(SUMIFS(Rohdaten!BP:BP,Rohdaten!$A:$A,Einzelabend!$C$3,Rohdaten!$D:$D,Einzelabend!$C6)*150)+(SUMIFS(Rohdaten!BW:BW,Rohdaten!$A:$A,Einzelabend!$C$3,Rohdaten!$D:$D,Einzelabend!$C6)*200) -> 0 | N15: =(SUMIFS(Rohdaten!AV:AV,Rohdaten!$A:$A,Einzelabend!$C$3,Rohdaten!$D:$D,Einzelabend!$C6)*40)+(SUMIFS(Rohdaten!BC:BC,Rohdaten!$A:$A,Einzelabend!$C$3,Rohdaten!$D:$D,Einzelabend!$C6)*100)+(SUMIFS(Rohdaten!BJ:BJ,Rohdaten!$A:$A,Einzelabend!$C$3,Rohdaten!$D:$D,Einzelabend!$C6)*200)+(SUMIFS(Rohdaten!BQ:BQ,Rohdaten!$A:$A,Einzelabend!$C$3,Rohdaten!$D:$D,Einzelabend!$C6)*300)+(SUMIFS(Rohdaten!BX:BX,Rohdaten!$A:$A,Einzelabend!$C$3,Rohdaten!$D:$D,Einzelabend!$C6)*400) -> 200 | O15: =(SUMIFS(Rohdaten!AW:AW,Rohdaten!$A:$A,Einzelabend!$C$3,Rohdaten!$D:$D,Einzelabend!$C6)*40)+(SUMIFS(Rohdaten!BD:BD,Rohdaten!$A:$A,Einzelabend!$C$3,Rohdaten!$D:$D,Einzelabend!$C6)*100)+(SUMIFS(Rohdaten!BK:BK,Rohdaten!$A:$A,Einzelabend!$C$3,Rohdaten!$D:$D,Einzelabend!$C6)*200)+(SUMIFS(Rohdaten!BR:BR,Rohdaten!$A:$A,Einzelabend!$C$3,Rohdaten!$D:$D,Einzelabend!$C6)*300)+(SUMIFS(Rohdaten!BY:BY,Rohdaten!$A:$A,Einzelabend!$C$3,Rohdaten!$D:$D,Einzelabend!$C6)*400) -> 0 | P15: =(SUMIFS(Rohdaten!AX:AX,Rohdaten!$A:$A,Einzelabend!$C$3,Rohdaten!$D:$D,Einzelabend!$C6)*80)+(SUMIFS(Rohdaten!BE:BE,Rohdaten!$A:$A,Einzelabend!$C$3,Rohdaten!$D:$D,Einzelabend!$C6)*200)+(SUMIFS(Rohdaten!BL:BL,Rohdaten!$A:$A,Einzelabend!$C$3,Rohdaten!$D:$D,Einzelabend!$C6)*400)+(SUMIFS(Rohdaten!BS:BS,Rohdaten!$A:$A,Einzelabend!$C$3,Rohdaten!$D:$D,Einzelabend!$C6)*600)+(SUMIFS(Rohdaten!BZ:BZ,Rohdaten!$A:$A,Einzelabend!$C$3,Rohdaten!$D:$D,Einzelabend!$C6)*800) -> 240 | Q15: =(SUMIFS(Rohdaten!AY:AY,Rohdaten!$A:$A,Einzelabend!$C$3,Rohdaten!$D:$D,Einzelabend!$C6)*60)+(SUMIFS(Rohdaten!BF:BF,Rohdaten!$A:$A,Einzelabend!$C$3,Rohdaten!$D:$D,Einzelabend!$C6)*150)+(SUMIFS(Rohdaten!BM:BM,Rohdaten!$A:$A,Einzelabend!$C$3,Rohdaten!$D:$D,Einzelabend!$C6)*300)+(SUMIFS(Rohdaten!BT:BT,Rohdaten!$A:$A,Einzelabend!$C$3,Rohdaten!$D:$D,Einzelabend!$C6)*450)+(SUMIFS(Rohdaten!CA:CA,Rohdaten!$A:$A,Einzelabend!$C$3,Rohdaten!$D:$D,Einzelabend!$C6)*600) -> 0 | R15: =(SUMIFS(Rohdaten!AZ:AZ,Rohdaten!$A:$A,Einzelabend!$C$3,Rohdaten!$D:$D,Einzelabend!$C6)*60)+(SUMIFS(Rohdaten!BG:BG,Rohdaten!$A:$A,Einzelabend!$C$3,Rohdaten!$D:$D,Einzelabend!$C6)*150)+(SUMIFS(Rohdaten!BN:BN,Rohdaten!$A:$A,Einzelabend!$C$3,Rohdaten!$D:$D,Einzelabend!$C6)*300)+(SUMIFS(Rohdaten!BU:BU,Rohdaten!$A:$A,Einzelabend!$C$3,Rohdaten!$D:$D,Einzelabend!$C6)*450)+(SUMIFS(Rohdaten!CB:CB,Rohdaten!$A:$A,Einzelabend!$C$3,Rohdaten!$D:$D,Einzelabend!$C6)*600) -> 60 | S15: =SUM(M15:R15) -> 500
C16: Team 1 | E16: Team 2 | H16: Differenz | L16: =C7 -> Küng | M16: =(SUMIFS(Rohdaten!AU:AU,Rohdaten!$A:$A,Einzelabend!$C$3,Rohdaten!$D:$D,Einzelabend!$C7)*20)+(SUMIFS(Rohdaten!BB:BB,Rohdaten!$A:$A,Einzelabend!$C$3,Rohdaten!$D:$D,Einzelabend!$C7)*50)+(SUMIFS(Rohdaten!BI:BI,Rohdaten!$A:$A,Einzelabend!$C$3,Rohdaten!$D:$D,Einzelabend!$C7)*100)+(SUMIFS(Rohdaten!BP:BP,Rohdaten!$A:$A,Einzelabend!$C$3,Rohdaten!$D:$D,Einzelabend!$C7)*150)+(SUMIFS(Rohdaten!BW:BW,Rohdaten!$A:$A,Einzelabend!$C$3,Rohdaten!$D:$D,Einzelabend!$C7)*200) -> 0 | N16: =(SUMIFS(Rohdaten!AV:AV,Rohdaten!$A:$A,Einzelabend!$C$3,Rohdaten!$D:$D,Einzelabend!$C7)*40)+(SUMIFS(Rohdaten!BC:BC,Rohdaten!$A:$A,Einzelabend!$C$3,Rohdaten!$D:$D,Einzelabend!$C7)*100)+(SUMIFS(Rohdaten!BJ:BJ,Rohdaten!$A:$A,Einzelabend!$C$3,Rohdaten!$D:$D,Einzelabend!$C7)*200)+(SUMIFS(Rohdaten!BQ:BQ,Rohdaten!$A:$A,Einzelabend!$C$3,Rohdaten!$D:$D,Einzelabend!$C7)*300)+(SUMIFS(Rohdaten!BX:BX,Rohdaten!$A:$A,Einzelabend!$C$3,Rohdaten!$D:$D,Einzelabend!$C7)*400) -> 0 | O16: =(SUMIFS(Rohdaten!AW:AW,Rohdaten!$A:$A,Einzelabend!$C$3,Rohdaten!$D:$D,Einzelabend!$C7)*40)+(SUMIFS(Rohdaten!BD:BD,Rohdaten!$A:$A,Einzelabend!$C$3,Rohdaten!$D:$D,Einzelabend!$C7)*100)+(SUMIFS(Rohdaten!BK:BK,Rohdaten!$A:$A,Einzelabend!$C$3,Rohdaten!$D:$D,Einzelabend!$C7)*200)+(SUMIFS(Rohdaten!BR:BR,Rohdaten!$A:$A,Einzelabend!$C$3,Rohdaten!$D:$D,Einzelabend!$C7)*300)+(SUMIFS(Rohdaten!BY:BY,Rohdaten!$A:$A,Einzelabend!$C$3,Rohdaten!$D:$D,Einzelabend!$C7)*400) -> 40 | P16: =(SUMIFS(Rohdaten!AX:AX,Rohdaten!$A:$A,Einzelabend!$C$3,Rohdaten!$D:$D,Einzelabend!$C7)*80)+(SUMIFS(Rohdaten!BE:BE,Rohdaten!$A:$A,Einzelabend!$C$3,Rohdaten!$D:$D,Einzelabend!$C7)*200)+(SUMIFS(Rohdaten!BL:BL,Rohdaten!$A:$A,Einzelabend!$C$3,Rohdaten!$D:$D,Einzelabend!$C7)*400)+(SUMIFS(Rohdaten!BS:BS,Rohdaten!$A:$A,Einzelabend!$C$3,Rohdaten!$D:$D,Einzelabend!$C7)*600)+(SUMIFS(Rohdaten!BZ:BZ,Rohdaten!$A:$A,Einzelabend!$C$3,Rohdaten!$D:$D,Einzelabend!$C7)*800) -> 240 | Q16: =(SUMIFS(Rohdaten!AY:AY,Rohdaten!$A:$A,Einzelabend!$C$3,Rohdaten!$D:$D,Einzelabend!$C7)*60)+(SUMIFS(Rohdaten!BF:BF,Rohdaten!$A:$A,Einzelabend!$C$3,Rohdaten!$D:$D,Einzelabend!$C7)*150)+(SUMIFS(Rohdaten!BM:BM,Rohdaten!$A:$A,Einzelabend!$C$3,Rohdaten!$D:$D,Einzelabend!$C7)*300)+(SUMIFS(Rohdaten!BT:BT,Rohdaten!$A:$A,Einzelabend!$C$3,Rohdaten!$D:$D,Einzelabend!$C7)*450)+(SUMIFS(Rohdaten!CA:CA,Rohdaten!$A:$A,Einzelabend!$C$3,Rohdaten!$D:$D,Einzelabend!$C7)*600) -> 60 | R16: =(SUMIFS(Rohdaten!AZ:AZ,Rohdaten!$A:$A,Einzelabend!$C$3,Rohdaten!$D:$D,Einzelabend!$C7)*60)+(SUMIFS(Rohdaten!BG:BG,Rohdaten!$A:$A,Einzelabend!$C$3,Rohdaten!$D:$D,Einzelabend!$C7)*150)+(SUMIFS(Rohdaten!BN:BN,Rohdaten!$A:$A,Einzelabend!$C$3,Rohdaten!$D:$D,Einzelabend!$C7)*300)+(SUMIFS(Rohdaten!BU:BU,Rohdaten!$A:$A,Einzelabend!$C$3,Rohdaten!$D:$D,Einzelabend!$C7)*450)+(SUMIFS(Rohdaten!CB:CB,Rohdaten!$A:$A,Einzelabend!$C$3,Rohdaten!$D:$D,Einzelabend!$C7)*600) -> 60 | S16: =SUM(M16:R16) -> 400
A17: Striche | C17: =SUMIFS(Rohdaten!$AQ:$AQ,Rohdaten!$C:$C,Einzelabend!$B6) -> 3 | E17: =SUMIFS(Rohdaten!$AQ:$AQ,Rohdaten!$C:$C,Einzelabend!$B8) -> 7 | H17: =C17-E17 -> -4 | L17: =C8 -> Goonse | M17: =(SUMIFS(Rohdaten!AU:AU,Rohdaten!$A:$A,Einzelabend!$C$3,Rohdaten!$D:$D,Einzelabend!$C8)*20)+(SUMIFS(Rohdaten!BB:BB,Rohdaten!$A:$A,Einzelabend!$C$3,Rohdaten!$D:$D,Einzelabend!$C8)*50)+(SUMIFS(Rohdaten!BI:BI,Rohdaten!$A:$A,Einzelabend!$C$3,Rohdaten!$D:$D,Einzelabend!$C8)*100)+(SUMIFS(Rohdaten!BP:BP,Rohdaten!$A:$A,Einzelabend!$C$3,Rohdaten!$D:$D,Einzelabend!$C8)*150)+(SUMIFS(Rohdaten!BW:BW,Rohdaten!$A:$A,Einzelabend!$C$3,Rohdaten!$D:$D,Einzelabend!$C8)*200) -> 0 | N17: =(SUMIFS(Rohdaten!AV:AV,Rohdaten!$A:$A,Einzelabend!$C$3,Rohdaten!$D:$D,Einzelabend!$C8)*40)+(SUMIFS(Rohdaten!BC:BC,Rohdaten!$A:$A,Einzelabend!$C$3,Rohdaten!$D:$D,Einzelabend!$C8)*100)+(SUMIFS(Rohdaten!BJ:BJ,Rohdaten!$A:$A,Einzelabend!$C$3,Rohdaten!$D:$D,Einzelabend!$C8)*200)+(SUMIFS(Rohdaten!BQ:BQ,Rohdaten!$A:$A,Einzelabend!$C$3,Rohdaten!$D:$D,Einzelabend!$C8)*300)+(SUMIFS(Rohdaten!BX:BX,Rohdaten!$A:$A,Einzelabend!$C$3,Rohdaten!$D:$D,Einzelabend!$C8)*400) -> 40 | O17: =(SUMIFS(Rohdaten!AW:AW,Rohdaten!$A:$A,Einzelabend!$C$3,Rohdaten!$D:$D,Einzelabend!$C8)*40)+(SUMIFS(Rohdaten!BD:BD,Rohdaten!$A:$A,Einzelabend!$C$3,Rohdaten!$D:$D,Einzelabend!$C8)*100)+(SUMIFS(Rohdaten!BK:BK,Rohdaten!$A:$A,Einzelabend!$C$3,Rohdaten!$D:$D,Einzelabend!$C8)*200)+(SUMIFS(Rohdaten!BR:BR,Rohdaten!$A:$A,Einzelabend!$C$3,Rohdaten!$D:$D,Einzelabend!$C8)*300)+(SUMIFS(Rohdaten!BY:BY,Rohdaten!$A:$A,Einzelabend!$C$3,Rohdaten!$D:$D,Einzelabend!$C8)*400) -> 200 | P17: =(SUMIFS(Rohdaten!AX:AX,Rohdaten!$A:$A,Einzelabend!$C$3,Rohdaten!$D:$D,Einzelabend!$C8)*80)+(SUMIFS(Rohdaten!BE:BE,Rohdaten!$A:$A,Einzelabend!$C$3,Rohdaten!$D:$D,Einzelabend!$C8)*200)+(SUMIFS(Rohdaten!BL:BL,Rohdaten!$A:$A,Einzelabend!$C$3,Rohdaten!$D:$D,Einzelabend!$C8)*400)+(SUMIFS(Rohdaten!BS:BS,Rohdaten!$A:$A,Einzelabend!$C$3,Rohdaten!$D:$D,Einzelabend!$C8)*600)+(SUMIFS(Rohdaten!BZ:BZ,Rohdaten!$A:$A,Einzelabend!$C$3,Rohdaten!$D:$D,Einzelabend!$C8)*800) -> 400 | Q17: =(SUMIFS(Rohdaten!AY:AY,Rohdaten!$A:$A,Einzelabend!$C$3,Rohdaten!$D:$D,Einzelabend!$C8)*60)+(SUMIFS(Rohdaten!BF:BF,Rohdaten!$A:$A,Einzelabend!$C$3,Rohdaten!$D:$D,Einzelabend!$C8)*150)+(SUMIFS(Rohdaten!BM:BM,Rohdaten!$A:$A,Einzelabend!$C$3,Rohdaten!$D:$D,Einzelabend!$C8)*300)+(SUMIFS(Rohdaten!BT:BT,Rohdaten!$A:$A,Einzelabend!$C$3,Rohdaten!$D:$D,Einzelabend!$C8)*450)+(SUMIFS(Rohdaten!CA:CA,Rohdaten!$A:$A,Einzelabend!$C$3,Rohdaten!$D:$D,Einzelabend!$C8)*600) -> 60 | R17: =(SUMIFS(Rohdaten!AZ:AZ,Rohdaten!$A:$A,Einzelabend!$C$3,Rohdaten!$D:$D,Einzelabend!$C8)*60)+(SUMIFS(Rohdaten!BG:BG,Rohdaten!$A:$A,Einzelabend!$C$3,Rohdaten!$D:$D,Einzelabend!$C8)*150)+(SUMIFS(Rohdaten!BN:BN,Rohdaten!$A:$A,Einzelabend!$C$3,Rohdaten!$D:$D,Einzelabend!$C8)*300)+(SUMIFS(Rohdaten!BU:BU,Rohdaten!$A:$A,Einzelabend!$C$3,Rohdaten!$D:$D,Einzelabend!$C8)*450)+(SUMIFS(Rohdaten!CB:CB,Rohdaten!$A:$A,Einzelabend!$C$3,Rohdaten!$D:$D,Einzelabend!$C8)*600) -> 0 | S17: =SUM(M17:R17) -> 700
L18: =C9 -> Chäli | M18: =(SUMIFS(Rohdaten!AU:AU,Rohdaten!$A:$A,Einzelabend!$C$3,Rohdaten!$D:$D,Einzelabend!$C9)*20)+(SUMIFS(Rohdaten!BB:BB,Rohdaten!$A:$A,Einzelabend!$C$3,Rohdaten!$D:$D,Einzelabend!$C9)*50)+(SUMIFS(Rohdaten!BI:BI,Rohdaten!$A:$A,Einzelabend!$C$3,Rohdaten!$D:$D,Einzelabend!$C9)*100)+(SUMIFS(Rohdaten!BP:BP,Rohdaten!$A:$A,Einzelabend!$C$3,Rohdaten!$D:$D,Einzelabend!$C9)*150)+(SUMIFS(Rohdaten!BW:BW,Rohdaten!$A:$A,Einzelabend!$C$3,Rohdaten!$D:$D,Einzelabend!$C9)*200) -> 0 | N18: =(SUMIFS(Rohdaten!AV:AV,Rohdaten!$A:$A,Einzelabend!$C$3,Rohdaten!$D:$D,Einzelabend!$C9)*40)+(SUMIFS(Rohdaten!BC:BC,Rohdaten!$A:$A,Einzelabend!$C$3,Rohdaten!$D:$D,Einzelabend!$C9)*100)+(SUMIFS(Rohdaten!BJ:BJ,Rohdaten!$A:$A,Einzelabend!$C$3,Rohdaten!$D:$D,Einzelabend!$C9)*200)+(SUMIFS(Rohdaten!BQ:BQ,Rohdaten!$A:$A,Einzelabend!$C$3,Rohdaten!$D:$D,Einzelabend!$C9)*300)+(SUMIFS(Rohdaten!BX:BX,Rohdaten!$A:$A,Einzelabend!$C$3,Rohdaten!$D:$D,Einzelabend!$C9)*400) -> 40 | O18: =(SUMIFS(Rohdaten!AW:AW,Rohdaten!$A:$A,Einzelabend!$C$3,Rohdaten!$D:$D,Einzelabend!$C9)*40)+(SUMIFS(Rohdaten!BD:BD,Rohdaten!$A:$A,Einzelabend!$C$3,Rohdaten!$D:$D,Einzelabend!$C9)*100)+(SUMIFS(Rohdaten!BK:BK,Rohdaten!$A:$A,Einzelabend!$C$3,Rohdaten!$D:$D,Einzelabend!$C9)*200)+(SUMIFS(Rohdaten!BR:BR,Rohdaten!$A:$A,Einzelabend!$C$3,Rohdaten!$D:$D,Einzelabend!$C9)*300)+(SUMIFS(Rohdaten!BY:BY,Rohdaten!$A:$A,Einzelabend!$C$3,Rohdaten!$D:$D,Einzelabend!$C9)*400) -> 140 | P18: =(SUMIFS(Rohdaten!AX:AX,Rohdaten!$A:$A,Einzelabend!$C$3,Rohdaten!$D:$D,Einzelabend!$C9)*80)+(SUMIFS(Rohdaten!BE:BE,Rohdaten!$A:$A,Einzelabend!$C$3,Rohdaten!$D:$D,Einzelabend!$C9)*200)+(SUMIFS(Rohdaten!BL:BL,Rohdaten!$A:$A,Einzelabend!$C$3,Rohdaten!$D:$D,Einzelabend!$C9)*400)+(SUMIFS(Rohdaten!BS:BS,Rohdaten!$A:$A,Einzelabend!$C$3,Rohdaten!$D:$D,Einzelabend!$C9)*600)+(SUMIFS(Rohdaten!BZ:BZ,Rohdaten!$A:$A,Einzelabend!$C$3,Rohdaten!$D:$D,Einzelabend!$C9)*800) -> 80 | Q18: =(SUMIFS(Rohdaten!AY:AY,Rohdaten!$A:$A,Einzelabend!$C$3,Rohdaten!$D:$D,Einzelabend!$C9)*60)+(SUMIFS(Rohdaten!BF:BF,Rohdaten!$A:$A,Einzelabend!$C$3,Rohdaten!$D:$D,Einzelabend!$C9)*150)+(SUMIFS(Rohdaten!BM:BM,Rohdaten!$A:$A,Einzelabend!$C$3,Rohdaten!$D:$D,Einzelabend!$C9)*300)+(SUMIFS(Rohdaten!BT:BT,Rohdaten!$A:$A,Einzelabend!$C$3,Rohdaten!$D:$D,Einzelabend!$C9)*450)+(SUMIFS(Rohdaten!CA:CA,Rohdaten!$A:$A,Einzelabend!$C$3,Rohdaten!$D:$D,Einzelabend!$C9)*600) -> 300 | R18: =(SUMIFS(Rohdaten!AZ:AZ,Rohdaten!$A:$A,Einzelabend!$C$3,Rohdaten!$D:$D,Einzelabend!$C9)*60)+(SUMIFS(Rohdaten!BG:BG,Rohdaten!$A:$A,Einzelabend!$C$3,Rohdaten!$D:$D,Einzelabend!$C9)*150)+(SUMIFS(Rohdaten!BN:BN,Rohdaten!$A:$A,Einzelabend!$C$3,Rohdaten!$D:$D,Einzelabend!$C9)*300)+(SUMIFS(Rohdaten!BU:BU,Rohdaten!$A:$A,Einzelabend!$C$3,Rohdaten!$D:$D,Einzelabend!$C9)*450)+(SUMIFS(Rohdaten!CB:CB,Rohdaten!$A:$A,Einzelabend!$C$3,Rohdaten!$D:$D,Einzelabend!$C9)*600) -> 480 | S18: =SUM(M18:R18) -> 1040
C19: Anzahl | D19: Punkte | E19: Anzahl | F19: Punkte | H19: Differenz
A20: Mätsch | C20: =SUMIFS(Rohdaten!$AO:$AO,Rohdaten!$C:$C,Einzelabend!$B$6) -> 0 | D20: =SUMIFS(Rohdaten!CO:CO,Rohdaten!C:C,Einzelabend!B6) -> 0 | E20: =SUMIFS(Rohdaten!$AO:$AO,Rohdaten!$C:$C,Einzelabend!$B$8) -> 1 | F20: =SUMIFS(Rohdaten!CO:CO,Rohdaten!C:C,Einzelabend!B8) -> 514 | H20: =C20-E20 -> -1 | I20: =D20-F20 -> -514
A21: Berg | C21: =SUMIFS(Rohdaten!$AP:$AP,Rohdaten!$C:$C,Einzelabend!$B$6) -> 1 | E21: =SUMIFS(Rohdaten!$AP:$AP,Rohdaten!$C:$C,Einzelabend!$B$8) -> 2 | H21: =C21-E21 -> -1
A23: Pünkt | C23: =SUMIFS(Rohdaten!O:O,Rohdaten!C:C,Einzelabend!B6) -> 7754 | E23: =SUMIFS(Rohdaten!O:O,Rohdaten!C:C,Einzelabend!B8) -> 8382 | H23: =C23-E23 -> -628
A24: Runde 1 | C24: =SUMIFS(Rohdaten!F:F,Rohdaten!C:C,Einzelabend!$B$6) -> 2617 | E24: =SUMIFS(Rohdaten!F:F,Rohdaten!C:C,Einzelabend!$B$8) -> 3130 | H24: =C24-E24 -> -513 | I24: =D24-F24 -> 0
A25: Runde 2 | C25: =SUMIFS(Rohdaten!G:G,Rohdaten!C:C,Einzelabend!$B$6) -> 3118 | E25: =SUMIFS(Rohdaten!G:G,Rohdaten!C:C,Einzelabend!$B$8) -> 2189 | H25: =C25-E25 -> 929 | I25: =D25-F25 -> 0
A26: Runde 3 | C26: =SUMIFS(Rohdaten!H:H,Rohdaten!C:C,Einzelabend!$B$6) -> 2019 | E26: =SUMIFS(Rohdaten!H:H,Rohdaten!C:C,Einzelabend!$B$8) -> 3063 | H26: =C26-E26 -> -1044 | I26: =D26-F26 -> 0
A27: Runde 4 | C27: =SUMIFS(Rohdaten!I:I,Rohdaten!C:C,Einzelabend!$B$6) -> 0 | E27: =SUMIFS(Rohdaten!I:I,Rohdaten!C:C,Einzelabend!$B$8) -> 0 | H27: =C27-E27 -> 0 | I27: =D27-F27 -> 0
A28: Runde 5 | C28: =SUMIFS(Rohdaten!J:J,Rohdaten!C:C,Einzelabend!$B$6) -> 0 | E28: =SUMIFS(Rohdaten!J:J,Rohdaten!C:C,Einzelabend!$B$8) -> 0 | H28: =C28-E28 -> 0 | I28: =D28-F28 -> 0
A29: Runde 6 | C29: =SUMIFS(Rohdaten!K:K,Rohdaten!C:C,Einzelabend!$B$6) -> 0 | E29: =SUMIFS(Rohdaten!K:K,Rohdaten!C:C,Einzelabend!$B$8) -> 0 | H29: =C29-E29 -> 0 | I29: =D29-F29 -> 0
C31: Anzahl | D31: Punkte | E31: Anzahl | F31: Punkte | H31: Differenz | K31: =C6 -> Fuchs | L31: =SUMIFS(Rohdaten!$U:$U,Rohdaten!$A:$A,Einzelabend!$C$3,Rohdaten!$D:$D,Einzelabend!$K31) -> 0
A32: Total Wiise | C32: =SUM(C33:C37) -> 11 | D32: =SUMIFS(Rohdaten!$CJ:$CJ,Rohdaten!$C:$C,Einzelabend!$B$6)+SUMIFS(Rohdaten!$CJ:$CJ,Rohdaten!$C:$C,Einzelabend!$B$7) -> 900 | E32: =SUM(E33:E37) -> 13 | F32: =SUMIFS(Rohdaten!$CJ:$CJ,Rohdaten!$C:$C,Einzelabend!$B$8)+SUMIFS(Rohdaten!$CJ:$CJ,Rohdaten!$C:$C,Einzelabend!$B$9) -> 1740 | H32: =C32-E32 -> -2 | I32: =D32-F32 -> -840 | K32: =C7 -> Küng | L32: =SUMIFS(Rohdaten!$U:$U,Rohdaten!$A:$A,Einzelabend!$C$3,Rohdaten!$D:$D,Einzelabend!$K32) -> 0
A33: 20er | C33: =SUMIFS(Rohdaten!$BA:$BA,Rohdaten!$C:$C,Einzelabend!$B$6)+SUMIFS(Rohdaten!$BA:$BA,Rohdaten!$C:$C,Einzelabend!$B$7) -> 10 | D33: =SUMIFS(Rohdaten!$CE:$CE,Rohdaten!$C:$C,Einzelabend!$B$6)+SUMIFS(Rohdaten!$CE:$CE,Rohdaten!$C:$C,Einzelabend!$B$7) -> 700 | E33: =SUMIFS(Rohdaten!$BA:$BA,Rohdaten!$C:$C,Einzelabend!$B$8)+SUMIFS(Rohdaten!$BA:$BA,Rohdaten!$C:$C,Einzelabend!$B$9) -> 8 | F33: =SUMIFS(Rohdaten!$CE:$CE,Rohdaten!$C:$C,Einzelabend!$B$8)+SUMIFS(Rohdaten!$CE:$CE,Rohdaten!$C:$C,Einzelabend!$B$9) -> 440 | H33: =C33-E33 -> 2 | I33: =D33-F33 -> 260 | K33: =C8 -> Goonse | L33: =SUMIFS(Rohdaten!$U:$U,Rohdaten!$A:$A,Einzelabend!$C$3,Rohdaten!$D:$D,Einzelabend!$K33) -> 1
A34: 50er | C34: =SUMIFS(Rohdaten!$BH:$BH,Rohdaten!$C:$C,Einzelabend!$B$6)+SUMIFS(Rohdaten!$BH:$BH,Rohdaten!$C:$C,Einzelabend!$B$7) -> 0 | D34: =SUMIFS(Rohdaten!$CF:$CF,Rohdaten!$C:$C,Einzelabend!$B$6)+SUMIFS(Rohdaten!$CF:$CF,Rohdaten!$C:$C,Einzelabend!$B$7) -> 0 | E34: =SUMIFS(Rohdaten!$BH:$BH,Rohdaten!$C:$C,Einzelabend!$B$8)+SUMIFS(Rohdaten!$BH:$BH,Rohdaten!$C:$C,Einzelabend!$B$9) -> 1 | F34: =SUMIFS(Rohdaten!$CF:$CF,Rohdaten!$C:$C,Einzelabend!$B$8)+SUMIFS(Rohdaten!$CF:$CF,Rohdaten!$C:$C,Einzelabend!$B$9) -> 100 | H34: =C34-E34 -> -1 | I34: =D34-F34 -> -100 | K34: =C9 -> Chäli | L34: =SUMIFS(Rohdaten!$U:$U,Rohdaten!$A:$A,Einzelabend!$C$3,Rohdaten!$D:$D,Einzelabend!$K34) -> 0
A35: 100er | C35: =SUMIFS(Rohdaten!$BO:$BO,Rohdaten!$C:$C,Einzelabend!$B$6)+SUMIFS(Rohdaten!$BO:$BO,Rohdaten!$C:$C,Einzelabend!$B$7) -> 1 | D35: =SUMIFS(Rohdaten!$CG:$CG,Rohdaten!$C:$C,Einzelabend!$B$6)+SUMIFS(Rohdaten!$CG:$CG,Rohdaten!$C:$C,Einzelabend!$B$7) -> 200 | E35: =SUMIFS(Rohdaten!$BO:$BO,Rohdaten!$C:$C,Einzelabend!$B$8)+SUMIFS(Rohdaten!$BO:$BO,Rohdaten!$C:$C,Einzelabend!$B$9) -> 4 | F35: =SUMIFS(Rohdaten!$CG:$CG,Rohdaten!$C:$C,Einzelabend!$B$8)+SUMIFS(Rohdaten!$CG:$CG,Rohdaten!$C:$C,Einzelabend!$B$9) -> 1200 | H35: =C35-E35 -> -3 | I35: =D35-F35 -> -1000
A36: 150er | C36: =SUMIFS(Rohdaten!$BV:$BV,Rohdaten!$C:$C,Einzelabend!$B$6)+SUMIFS(Rohdaten!$BV:$BV,Rohdaten!$C:$C,Einzelabend!$B$7) -> 0 | D36: =SUMIFS(Rohdaten!$CH:$CH,Rohdaten!$C:$C,Einzelabend!$B$6)+SUMIFS(Rohdaten!$CH:$CH,Rohdaten!$C:$C,Einzelabend!$B$7) -> 0 | E36: =SUMIFS(Rohdaten!$BV:$BV,Rohdaten!$C:$C,Einzelabend!$B$8)+SUMIFS(Rohdaten!$BV:$BV,Rohdaten!$C:$C,Einzelabend!$B$9) -> 0 | F36: =SUMIFS(Rohdaten!$CH:$CH,Rohdaten!$C:$C,Einzelabend!$B$8)+SUMIFS(Rohdaten!$CH:$CH,Rohdaten!$C:$C,Einzelabend!$B$9) -> 0 | H36: =C36-E36 -> 0 | I36: =D36-F36 -> 0
A37: 200er | C37: =SUMIFS(Rohdaten!$CC:$CC,Rohdaten!$C:$C,Einzelabend!$B$6)+SUMIFS(Rohdaten!$CC:$CC,Rohdaten!$C:$C,Einzelabend!$B$7) -> 0 | D37: =SUMIFS(Rohdaten!$CI:$CI,Rohdaten!$C:$C,Einzelabend!$B$6)+SUMIFS(Rohdaten!$CI:$CI,Rohdaten!$C:$C,Einzelabend!$B$7) -> 0 | E37: =SUMIFS(Rohdaten!$CC:$CC,Rohdaten!$C:$C,Einzelabend!$B$8)+SUMIFS(Rohdaten!$CC:$CC,Rohdaten!$C:$C,Einzelabend!$B$9) -> 0 | F37: =SUMIFS(Rohdaten!$CI:$CI,Rohdaten!$C:$C,Einzelabend!$B$8)+SUMIFS(Rohdaten!$CI:$CI,Rohdaten!$C:$C,Einzelabend!$B$9) -> 0 | H37: =C37-E37 -> 0 | I37: =D37-F37 -> 0
A38: Anteil Wiise an Total | C38: =D32/C23 -> 0.11606913 | E38: =F32/E23 -> 0.20758769 | H38: =IF(C38>E38,(C38-E38)/E38,(E38-C38)/C38) -> 0.78848326
A40: Total Spenden | C40: =SUMIFS(Rohdaten!$AT:$AT,Rohdaten!$C:$C,Einzelabend!$B$6)+SUMIFS(Rohdaten!$AT:$AT,Rohdaten!$C:$C,Einzelabend!$B$7) -> 80 | E40: =SUMIFS(Rohdaten!$AT:$AT,Rohdaten!$C:$C,Einzelabend!$B$8)+SUMIFS(Rohdaten!$AT:$AT,Rohdaten!$C:$C,Einzelabend!$B$9) -> 0 | H40: =C40-E40 -> 80

Sheet Rohdaten
A1: Jassstatistik Wädi
A4: Datum | B4: Team | D4: Spieler | E4: Teamkonstellation | F4: Punkte Spiel 1 | G4: Punkte Spiel 2 | H4: Punkte Spiel 3 | I4: Punkte Spiel 4 | J4: Punkte Spiel 5 | K4: Punkte Spiel 6 | L4: Punkte Spiel 7 | M4: Punkte Spiel 8 | N4: Punkte Spiel 9 | O4: Punkte Total | P4: Anz. Spiele | Q4: Rundensiege | R4: Teilnahmen | S4: Vorhand | T4: Schub | U4: JFK | V4: Vorhand | W4: Vorhand | X4: Vorhand | Y4: Vorhand | Z4: Vorhand | AA4: Vorhand | AB4: Schieben | AC4: Schieben | AD4: Schieben | AE4: Schieben | AF4: Schieben | AG4: Schieben | AH4: Anteil Vorhand | AI4: Match 1x | AJ4: Match 2x | AK4: Match 2x | AL4: Match 4x | AM4: Match 3x | AN4: Match 3x | AO4: Match Total | AP4: Berg | AQ4: Striche | AR4: Schneider | AS4: Kontermatch | AT4: Spenden | AU4: Anz. 20 1fach | AV4: Anz. 20 2fach | AW4: Anz. 20 2fach | AX4: Anz. 20 4fach | AY4: Anz. 20 3fach | AZ4: Anz. 20 3fach | BA4: Total Anz. 20 | BB4: Anz. 50 1fach | BC4: Anz. 50 2fach | BD4: Anz. 50 2fach | BE4: Anz. 50 4fach | BF4: Anz. 50 3fach | BG4: Anz. 50 3fach | BH4: Total Anz. 50 | BI4: Anz. 100 1fach | BJ4: Anz. 100 2fach | BK4: Anz. 100 2fach | BL4: Anz. 100 4fach | BM4: Anz. 100 3fach | BN4: Anz. 100 3fach | BO4: Total Anz. 100 | BP4: Anz. 150 1fach | BQ4: Anz. 150 2fach | BR4: Anz. 150 2fach | BS4: Anz. 150 4fach | BT4: Anz. 150 3fach | BU4: Anz. 150 3fach | BV4: Total Anz. 150 | BW4: Anz. 200 1fach | BX4: Anz. 200 2fach | BY4: Anz. 200 2fach | BZ4: Anz. 200 4fach | CA4: Anz. 200 3fach | CB4: Anz. 200 3fach | CC4: Total Anz. 200 | CE4: Punkte 20 | CF4: Punkte 50 | CG4: Punkte 100 | CH4: Punkte 150 | CI4: Punkte 200 | CJ4: Total Weisen | CK4: Punkte Match 1x | CL4: Punkte Match 2x | CM4: Punkte Match 3x | CN4: Punkte Match 4x | CO4: Total Match | CQ4: Rank. Total Striche | CR4: Rank. Total Berg | CS4: ø Striche | CT4: Rank. ø Striche | CU4: Rank. Schneider | CV4: Rank. Punkte | CW4: ø Punkte | CX4: Rank ø Punkte | CY4: Rank Anz. Match | CZ4: Rank Punkte Match | DA4: Rank Anz. Match 1fach | DB4: Rank Anz. Match 2fach | DC4: Rank Anz. Match 3fach | DD4: Rank Anz. Match 4fach | DE4: Rank Punkte Weisen | DF4: Rank Anz. 20er | DG4: Rank Punkte 20er | DH4: Rank Anz. 50er | DI4: Rank Punkte 50er | DJ4: Rank Anz. 100er | DK4: Rank Punkte 100er | DL4: Rank Anz. 150er | DM4: Rank Punkte 150er | DN4: Rank Anz. 200er | DO4: Rank Punkte 200er | DP4: Tagessieg | DQ4: Rank Tagessieg | DR4: Rank Teilnahmen | DS4: Rank Spenden | DT4: ø Spende/Abend | DU4: Rank ø Spende/Abend | DV4: ø Anzahl Punkte/Spiel | DW4: ø Rank Anzahl Punkte/Spiel | DX4: ø Anzahl Striche/Spiel | DY4: ø Rank Anzahl Punkte/Spiel | DZ4: Rank. Kontermatch | EA4: Rank. Rundensiege | EB4: Rank JFK | EC4: Chefschwätzer | EL4: Spieler | EN4: Wiisanteil | EO4: Sieger hat weniger Punkte
A5: 46102 | B5: Team 1 | C5: =A5&B5 -> 46102Team 1 | D5: Fuchs | E5: =D5&D6 -> FuchsKüng | F5: 3002 | G5: 3157 | H5: 3340 | I5: 2444 | J5: 2591 | K5: 3011 | O5: =IF(SUM(F5:N5)=0,"",SUM(F5:N5)) -> 17545 | P5: =IF(COUNTA(F5:N5)=0,"",COUNTA(F5:N5)) -> 6 | Q5: 3 | R5: 1 | S5: =SUM(V5:AA5) -> 6 | T5: =SUM(AB6:AG6) -> 10 | X5: 1 | Y5: 2 | Z5: 2 | AA5: 1 | AC5: 3 | AE5: 4 | AG5: 3 | AH5: =IFERROR(S5/(S5+T5),"") -> 0.375 | AO5: =SUM(AI5:AN5) -> 0 | AP5: 2 | AQ5: 8 | AT5: 30 | AV5: 4 | AX5: 1 | AY5: 4 | AZ5: 2 | BA5: =SUM(AU5:AZ5) -> 11 | BE5: 1 | BH5: =SUM(BB5:BG5) -> 1 | BO5: =SUM(BI5:BN5) -> 0 | BV5: =SUM(BP5:BU5) -> 0 | CC5: =SUM(BW5:CB5) -> 0 | CE5: =(AU5*20)+(AV5*40)+(AW5*40)+(AX5*80)+(AY5*60)+(AZ5*60) -> 600 | CF5: =(BB5*50)+(BC5*100)+(BD5*100)+(BE5*200)+(BF5*150)+(BG5*150) -> 200 | CG5: =(BI5*100)+(BJ5*200)+(BK5*200)+(BL5*400)+(BM5*300)+(BN5*300) -> 0 | CH5: =(BP5*150)+(BQ5*300)+(BR5*300)+(BS5*600)+(BT5*450)+(BU5*450) -> 0 | CI5: =(BW5*200)+(BX5*400)+(BY5*400)+(BZ5*800)+(CA5*600)+(CB5*600) -> 0 | CJ5: =SUM(CE5:CI5) -> 800 | CK5: =AI5*257 -> 0 | CL5: =(AJ5*514)+(AK5*514) -> 0 | CM5: =(AM5*771)+(AN5*771) -> 0 | CN5: =AL5*1028 -> 0 | CO5: =SUM(CK5:CN5) -> 0 | DP5: =IF(_xlfn.RANK.EQ(AQ5,$AQ$5:$AQ$8,0)=1,1,"") | EC5: =IF(_xlfn.RANK.EQ(CJ5,$CJ$5:$CJ$8,0)=1,1,"") | EL5: =D5 -> Fuchs | EN5: =(CJ5+CJ6)/(O5) -> 0.12197207 | EO5: =IF(AND(DP5=1,O5<O7),1,"")
A6: 46102 | B6: Team 1.1 | C6: =A6&B6 -> 46102Team 1.1 | D6: Küng | F6: 3002 | G6: 3157 | H6: 3340 | I6: 2444 | J6: 2591 | K6: 3011 | O6: =IF(SUM(F6:N6)=0,"",SUM(F6:N6)) -> 17545 | P6: =IF(COUNTA(F6:N6)=0,"",COUNTA(F6:N6)) -> 6 | Q6: 3 | R6: 1 | S6: =SUM(V6:AA6) -> 5 | T6: =SUM(AB5:AG5) -> 10 | U6: 1 | Y6: 3 | Z6: 2 | AC6: 3 | AD6: 1 | AE6: 5 | AF6: 1 | AH6: =IFERROR(S6/(S6+T6),"") -> 0.33333333 | AO6: =SUM(AI6:AN6) -> 0 | AP6: 2 | AQ6: 8 | AT6: 30 | AX6: 3 | AY6: 4 | AZ6: 1 | BA6: =SUM(AU6:AZ6) -> 8 | BE6: 2 | BH6: =SUM(BB6:BG6) -> 2 | BL6: 1 | BO6: =SUM(BI6:BN6) -> 1 | BV6: =SUM(BP6:BU6) -> 0 | CC6: =SUM(BW6:CB6) -> 0 | CE6: =(AU6*20)+(AV6*40)+(AW6*40)+(AX6*80)+(AY6*60)+(AZ6*60) -> 540 | CF6: =(BB6*50)+(BC6*100)+(BD6*100)+(BE6*200)+(BF6*150)+(BG6*150) -> 400 | CG6: =(BI6*100)+(BJ6*200)+(BK6*200)+(BL6*400)+(BM6*300)+(BN6*300) -> 400 | CH6: =(BP6*150)+(BQ6*300)+(BR6*300)+(BS6*600)+(BT6*450)+(BU6*450) -> 0 | CI6: =(BW6*200)+(BX6*400)+(BY6*400)+(BZ6*800)+(CA6*600)+(CB6*600) -> 0 | CJ6: =SUM(CE6:CI6) -> 1340 | CK6: =AI6*257 -> 0 | CL6: =(AJ6*514)+(AK6*514) -> 0 | CM6: =(AM6*771)+(AN6*771) -> 0 | CN6: =AL6*1028 -> 0 | CO6: =SUM(CK6:CN6) -> 0 | DP6: =IF(_xlfn.RANK.EQ(AQ6,$AQ$5:$AQ$8,0)=1,1,"") | EC6: =IF(_xlfn.RANK.EQ(CJ6,$CJ$5:$CJ$8,0)=1,1,"") | EL6: =D6 -> Küng
A7: 46102 | B7: Team 2 | C7: =A7&B7 -> 46102Team 2 | D7: Goonse | E7: =D7&D8 -> GoonseChäli | F7: 2487 | G7: 2739 | H7: 3036 | I7: 3445 | J7: 3049 | K7: 3054 | O7: =IF(SUM(F7:N7)=0,"",SUM(F7:N7)) -> 17810 | P7: =IF(COUNTA(F7:N7)=0,"",COUNTA(F7:N7)) -> 6 | Q7: 3 | R7: 1 | S7: =SUM(V7:AA7) -> 5 | T7: =SUM(AB8:AG8) -> 10 | U7: 2 | Y7: 1 | Z7: 4 | AB7: 2 | AC7: 1 | AE7: 3 | AG7: 3 | AH7: =IFERROR(S7/(S7+T7),"") -> 0.33333333 | AN7: 1 | AO7: =SUM(AI7:AN7) -> 1 | AP7: 4 | AQ7: 11 | AU7: 1 | AV7: 1 | AX7: 4 | AY7: 3 | AZ7: 1 | BA7: =SUM(AU7:AZ7) -> 10 | BC7: 1 | BH7: =SUM(BB7:BG7) -> 1 | BO7: =SUM(BI7:BN7) -> 0 | BS7: 1 | BV7: =SUM(BP7:BU7) -> 1 | CC7: =SUM(BW7:CB7) -> 0 | CE7: =(AU7*20)+(AV7*40)+(AW7*40)+(AX7*80)+(AY7*60)+(AZ7*60) -> 620 | CF7: =(BB7*50)+(BC7*100)+(BD7*100)+(BE7*200)+(BF7*150)+(BG7*150) -> 100 | CG7: =(BI7*100)+(BJ7*200)+(BK7*200)+(BL7*400)+(BM7*300)+(BN7*300) -> 0 | CH7: =(BP7*150)+(BQ7*300)+(BR7*300)+(BS7*600)+(BT7*450)+(BU7*450) -> 600 | CI7: =(BW7*200)+(BX7*400)+(BY7*400)+(BZ7*800)+(CA7*600)+(CB7*600) -> 0 | CJ7: =SUM(CE7:CI7) -> 1320 | CK7: =AI7*257 -> 0 | CL7: =(AJ7*514)+(AK7*514) -> 0 | CM7: =(AM7*771)+(AN7*771) -> 771 | CN7: =AL7*1028 -> 0 | CO7: =SUM(CK7:CN7) -> 771 | DP7: =IF(_xlfn.RANK.EQ(AQ7,$AQ$5:$AQ$8,0)=1,1,"") -> 1 | EC7: =IF(_xlfn.RANK.EQ(CJ7,$CJ$5:$CJ$8,0)=1,1,"") | EL7: =D7 -> Goonse | EN7: =(CJ7+CJ8)/(O7) -> 0.23020775 | EO7: =IF(AND(DP7=1,O7<O5),1,"")
